Workbook
Name 七彩喷射: 法术大全!$M$62
Name 万事通: 图表!$CE$4
Name 万箭齐发: 法术大全!$M$342
Name 不动物件: 法术大全!$M$160
Name 不屈: 图表!$CQ$7
Name 不屈勇武: 图表!$CU$13
Name 不死生物召唤术_召唤不死灵魄: 法术大全!$M$266
Name 不灭明焰: 法术大全!$M$138
Name 不谐低语: 法术大全!$M$72
Name 丘陵矮人属性值加成: 图表!$BQ$48
Name 丝绳_50尺: 图表!$AC$83
Name 中甲: 图表!$U$48:$U$52
Name 中甲大师: 图表!$CY$25
Name 中甲运用: 图表!$CY$27
Name 乌斯伽部族成员工具熟练项: 图表!$BK$69
Name 乌斯伽部族成员技能熟练项: 图表!$BK$67
Name 乌斯伽部族成员牵绊: 图表!$BK$52:$BK$57
Name 乌斯伽部族成员特点: 图表!$BK$36:$BK$43
Name 乌斯伽部族成员理想: 图表!$BK$45:$BK$50
Name 乌斯伽部族成员缺点: 图表!$BK$59:$BK$64
Name 乌斯伽部族成员背景装备: 图表!$BK$73
Name 乌斯伽部族成员额外语言: 图表!$BK$71
Name 书: 图表!$AC$22
Name 书法工具: 图表!$AC$102
Name 云雾术: 法术大全!$M$82
Name 亚比达奇凋死术: 法术大全!$M$467
Name 亡者丧钟: 法术大全!$M$43
Name 交友术: 法术大全!$M$12
Name 人类: 图表!$BS$35:$BY$35
Name 人类定身术: 法术大全!$M$159
Name 人类属性值加成: 图表!$BQ$35
Name 以太化: 法术大全!$M$445
Name 仪式施法者: 图表!$CY$32
Name 任意门: 法术大全!$M$293
Name 休憩曲: 图表!$CE$5
Name 众星冠冕: 法术大全!$M$441
Name 传讯术: 法术大全!$M$23
Name 传送术: 法术大全!$M$462
Name 传送法阵: 法术大全!$M$383
Name 伪装术: 法术大全!$M$376
Name 低身之机敏: 图表!$CY$57
Name 侍僧工具熟练项: 图表!$AH$69
Name 侍僧技能熟练项: 图表!$AH$67
Name 侍僧牵绊: 图表!$AH$52:$AH$57
Name 侍僧特殊选项: 图表!$AH$75
Name 侍僧特点: 图表!$AH$36:$AH$43
Name 侍僧理想: 图表!$AH$45:$AH$50
Name 侍僧缺点: 图表!$AH$59:$AH$64
Name 侍僧背景装备: 图表!$AH$73
Name 侍僧额外语言: 图表!$AH$71
Name 侏儒: 图表!$BS$46:$BV$46
Name 侦测善恶: 法术大全!$M$68
Name 侦测思想: 法术大全!$M$143
Name 侦测毒性和疾病: 法术大全!$M$70
Name 侦测魔法: 法术大全!$M$69
Name 便携式攻城锤: 图表!$AC$79
Name 信仰守卫: 法术大全!$M$306
Name 修复术: 法术大全!$M$22
Name 修补工具: 图表!$AC$114
Name 借鉴才学: 法术大全!$M$205

Sheet 角色
A1: 角色 Character
B3: 角色名 | R3: 技能熟练项
B4: 玩家名 | E4: 作者：太易，熊妈妈2D6 | R4: 工具熟练项
R5: 背景语言
B6: 种族 | E6: 精灵 | J6: 阵营 | M6: 混乱邪恶 | R6: 背景装备
B7: 性别 | E7: 女 | J7: 年龄 | R7: 特殊选项
B8: 亚种 | E8: 高等 | J8: 信仰
R9: 背景特性
B10: 背景 | E10: 智者 | J10: 发色
B11: 身高 | E11: 168 | J11: 肤色
B12: 体重 | J12: 瞳色
B13: 外貌描述
B14: 角色外貌
R15: 所选特点 | W15: 聪慧，想象力强
R16: 所选理想 | W16: 求道
R17: 所选牵绊
R18: 所选缺点
B19: 角色形象 | R19: 背景故事
R20: 访仙求古，方得克苏鲁。

Sheet 主要情况
A1: 主要情况 Main Interface | AV1: 职业特性 | BM1: 种族特性
W2: 等级 | AH2: 角色形象 | AV2: LV | AW2: 名称 | BB2: 描述 | BM2: 名称 | BS2: 描述
B3: 角色名 | E3: karma | P3: 主职业 | S3: 邪术师 | W3: 5 | Z3: 熟练加值 | AC3: =IF(图表!F6<5,2,IF(图表!F6<9,3,IF(图表!F6<13,4,IF(图表!F6<17,5,6)))) -> 3 | AW3: 链之魔契
B4: 玩家名 | P4: 兼职 | Z4: 经验值 | AW4: 融身入影
P5: 兼职Ⅱ
B6: 属性 | N6: 战斗
B7: 熟练 | E7: 属性值 | G7: 调整值 | I7: 修正→ | K7: 豁免 | S7: 修正 | Y7: 现有值 | AC7: 最大值
B8: =IF(OR($S$3="战士",$S$3="武僧",$S$3="游侠",$S$3="野蛮人"),"O","X") -> X | C8: 力量 | E8: 10 | G8: =INT(E8/2-5) -> 0 | K8: =G8+IF(B8="O",$AC$3,0)+I8 -> 0 | N8: 先攻 | P8: =G10+S8+IF(COUNTIF(BN15:BR21,"警觉"),5,)+IF(OR(AND($S$3="吟游诗人",$W$3>=2),AND($S$4="吟游诗人",$W$4>=2)),INT(AC3/2),) -> 3 | R8: < | V8: HP | AB8: / | AC8: =图表!J5+W3*(AC12+图表!G5+AE12)+图表!F8+图表!F10 -> 28
B10: =IF(OR($S$3="吟游诗人",$S$3="武僧",$S$3="游荡者",$S$3="游侠"),"O","X") -> X | C10: 敏捷 | E10: 16 | G10: =INT(E10/2-5) -> 3 | K10: =G10+IF(B10="O",$AC$3,0)+I10 -> 3 | N10: AC | P10: =IF(OR(L23="重甲",L23="无甲"),AD23,SUM(AD23,IF(AG23>0,IF(AG23>G10,G10,AG23),G10)))+S10+IF(S12="是",AP23,0) -> 15 | R10: < | V10: 生命骰数量 | AB10: / | AC10: =W3+W4+W5 -> 5
V11: =图表!P14 -> 已知祈唤 | AB11: / | AC11: =图表!S14 -> 3
B12: =IF(OR($S$3="战士",$S$3="术士",$S$3="野蛮人",$S$3="奇械师"),"O","X") -> X | C12: 体质 | E12: 10 | G12: =INT(E12/2-5) -> 0 | K12: =G12+IF(B12="O",$AC$3,0)+I12 -> 0 | N12: 装备盾牌 | S12: 否 | V12: 生命值成长 | Y12: =图表!D14 -> 1d8 | AB12: + | AC12: =G12 -> 0 | AE12: =IF(角色!E8="丘陵矮人",1,)+IF(COUNTIF(主要情况!BN15:BR21,"健壮"),2,) -> 0
V13: 特殊能力数值 | BM13: 属性值提升/专长
B14: =IF(OR($S$3="德鲁伊",$S$3="法师",$S$3="游荡者",$S$3="奇械师"),"O","X") -> X | C14: 智力 | E14: 14 | G14: =INT(E14/2-5) -> 2 | K14: =G14+IF(B14="O",$AC$3,0)+I14 -> 2 | N14: DC | P14: =SUM(8+AC3+IF(R17="力量",G8,IF(R17="敏捷",G10,IF(R17="体质",G12,IF(R17="智力",G14,IF(R17="感知",G16,IF(R17="魅力",G18,0)))))))+S14 -> 14 | R14: < | V14: 特殊能力数值 | AA14: 临时HP | BM14: LV | BN14: 名称 | BS14: 描述
BM15: 4 | BN15: 幸运
B16: =IF(OR($S$3="邪术师",$S$3="德鲁伊",$S$3="法师",$S$3="牧师",$S$3="圣武士"),"O","X") -> O | C16: 感知 | E16: 12 | G16: =INT(E16/2-5) -> 1 | K16: =G16+IF(B16="O",$AC$3,0)+I16 -> 4 | BM16: 8
N17: 关键属性 | R17: =图表!D28 -> 魅力 | V17: 体型 | X17: 中型 | AA17: 速度 | AD17: 30 | AF17: 尺 | BM17: 12
B18: =IF(OR($S$3="吟游诗人",$S$3="邪术师",$S$3="牧师",$S$3="圣武士",$S$3="术士"),"O","X") -> O | C18: 魅力 | E18: 16 | G18: =INT(E18/2-5) -> 3 | K18: =G18+IF(B18="O",$AC$3,0)+I18 -> 6 | BM18: 16
N19: 被动察觉 | R19: =10+I35+IF(COUNTIF(BN15:BR21,"观察力"),5,) -> 13 | V19: 抗性/免疫 | BM19: 19
E20: 0 | BM20: 6
B21: 技能 | L21: 主要装备 | AM21: 盾牌 | BM21: 10
B22: 熟练 | C22: 技能名 | F22: 修正 | I22: 总值 | L22: 护甲 | O22: 名称 | S22: 需要同调 | V22: 特性 | AA22: 重量 | AD22: AC | AF22: 最大敏捷 | AJ22: 隐匿劣势 | AM22: 盾牌名称 | AP22: AC | AR22: 重量
B23: X | C23: 运动 | H23: > | I23: =$G$8+F23+IF(B23="O",$AC$3,(IF(B23="❂",$AC$3*2,IF(B23="〄",INT($AC$3/2),0)))) -> 0 | L23: 轻甲 | N23: > | O23: 镶钉皮甲 | T23: X | AA23: =IFERROR(VLOOKUP(O23,图表!U45:X59,4,0),"") -> 13 | AC23: > | AD23: =IFERROR(VLOOKUP(O23,图表!U45:V59,2,0),IF(L23="无甲",10+G10,10)) -> 12 | AF23: + | AG23: =IF(AND(COUNTIF(BN15:BR21,"中甲大师"),L23="中甲"),3,IF(L23="中甲",2,"")) | AJ23: =IFERROR(VLOOKUP(O23,图表!U45:W59,3,0),"") -> 否 | AP23: 2 | AR23: 6 | BM23: 特殊能力（狂暴、引导神力等）
B24: 敏捷系 | L24: 武器 | O24: 名称 | S24: 需要同调 | V24: 特性 | AA24: 使用属性 | AD24: 攻击命中加值 | AI24: 武器伤害 | AM24: 伤害类型 | AP24: 重量 | AR24: 弹药数 | BM24: LV | BN24: 名称 | BS24: 描述
B25: X | C25: 特技 | H25: > | I25: =$G$10+F25+IF(B25="O",$AC$3,(IF(B25="❂",$AC$3*2,IF(B25="〄",INT($AC$3/2),0)))) -> 3 | L25: 右手 | N25: > | O25: 扇子 | T25: X | U25: =图表!Y66 -> #N/A | AC25: > | AD25: d20+ | AF25: =IFERROR(VLOOKUP(AA25,C8:H19,5,0)+IF('BUY点计算器&武器调整栏'!A16="是",AC3,)+'BUY点计算器&武器调整栏'!B16,"-") -> - | AH25: > | AI25: =IFERROR(图表!V66,"-") -> - | AM25: =图表!W66 -> #N/A | AP25: =图表!Z66 -> #N/A | AR25: 箭 | AS25: 0 | BN25: 邪魔活力
B26: X | C26: 巧手 | H26: > | I26: =$G$10+F26+IF(B26="O",$AC$3,(IF(B26="❂",$AC$3*2,IF(B26="〄",INT($AC$3/2),0)))) -> 3 | L26: 左手 | N26: > | O26: 铁链 | T26: X | U26: =图表!Y67 -> #N/A | AC26: > | AD26: d20+ | AF26: =IFERROR(VLOOKUP(AA26,C8:H19,5,0)+IF('BUY点计算器&武器调整栏'!A19="是",AC3,)+'BUY点计算器&武器调整栏'!B19,"-") -> - | AH26: > | AI26: =IFERROR(图表!V67,"-") -> - | AM26: =图表!W67 -> #N/A | AP26: =图表!Z67 -> #N/A | AR26: 矢 | AS26: 0 | BN26: 千面之脸
B27: X | C27: 隐匿 | H27: > | I27: =$G$10+F27+IF(B27="O",$AC$3,(IF(B27="❂",$AC$3*2,IF(B27="〄",INT($AC$3/2),0)))) -> 3 | L27: 双手 | N27: > | T27: X | U27: =图表!Y68 -> - | AC27: > | AD27: d20+ | AF27: =IFERROR(VLOOKUP(AA27,C8:H19,5,0)+IF('BUY点计算器&武器调整栏'!A22="是",AC3,)+'BUY点计算器&武器调整栏'!B22,"-") -> - | AH27: > | AI27: =IFERROR(图表!V68,"-") -> - | AM27: =图表!W68 -> - | AP27: =图表!Z68 -> - | AR27: 弹 | AS27: 0
B28: 智力系 | L28: X | N28: > | T28: X | U28: - | AC28: > | AD28: d20+ | AF28: - | AH28: > | AI28: - | AM28: - | AP28: - | AR28: 投 | AS28: 0
B29: X | C29: 调查 | H29: > | I29: =$G$14+F29+IF(B29="O",$AC$3,(IF(B29="❂",$AC$3*2,IF(B29="〄",INT($AC$3/2),0)))) -> 2 | L29: X | N29: > | T29: X | U29: - | AC29: > | AD29: d20+ | AF29: - | AH29: > | AI29: - | AM29: - | AP29: - | AR29: 它 | AS29: 0
B30: X | C30: 奥秘 | F30: 2 | H30: > | I30: =$G$14+F30+IF(B30="O",$AC$3,(IF(B30="❂",$AC$3*2,IF(B30="〄",INT($AC$3/2),0)))) -> 4 | L30: 其他 | O30: 名称 | S30: 需要同调 | V30: 特性 | AA30: 重量
B31: X | C31: 历史 | F31: 2 | H31: > | I31: =$G$14+F31+IF(B31="O",$AC$3,(IF(B31="❂",$AC$3*2,IF(B31="〄",INT($AC$3/2),0)))) -> 4 | L31: 头部 | N31: > | T31: X | AD31: 常用法术 | AV31: 武器及护甲熟练
B32: X | C32: 自然 | H32: > | I32: =$G$14+F32+IF(B32="O",$AC$3,(IF(B32="❂",$AC$3*2,IF(B32="〄",INT($AC$3/2),0)))) -> 2 | L32: 颈部 | N32: > | T32: X | AD32: 法术名称 | AI32: 法术攻击加值 | AN32: 伤害 | AQ32: 伤害类型 | AV32: 武器
B33: X | C33: 宗教 | F33: 2 | H33: > | I33: =$G$14+F33+IF(B33="O",$AC$3,(IF(B33="❂",$AC$3*2,IF(B33="〄",INT($AC$3/2),0)))) -> 4 | L33: 肩部 | N33: > | T33: X | AI33: > | AJ33: =施法!V2 -> 6 | AL33: > | AV33: 护甲
B34: 感知系 | L34: 背部 | N34: > | O34: 自然斗篷 | T34: X | AI34: > | AJ34: =施法!V2 -> 6 | AL34: > | AV34: 其他特性 | BM34: 职业装备、豁免熟练与技能熟练
B35: X | C35: 察觉 | F35: 2 | H35: > | I35: =$G$16+F35+IF(B35="O",$AC$3,(IF(B35="❂",$AC$3*2,IF(B35="〄",INT($AC$3/2),0)))) -> 3 | L35: 胸部 | N35: > | T35: X | AM35: 环阶 | AO35: 法术位 | AV35: 语言 | AZ35: 通用语，精灵语，古神语
B36: X | C36: 洞悉 | H36: > | I36: =$G$16+F36+IF(B36="O",$AC$3,(IF(B36="❂",$AC$3*2,IF(B36="〄",INT($AC$3/2),0)))) -> 1 | L36: 腕部 | N36: > | T36: X | AD36: 关键属性 | AI36: =施法!H2 -> 魅力 | AM36: 1 | AO36: =施法!AX5 -> 0 | AQ36: / | AR36: =施法!BA5 -> 0 | AV36: 工具
B37: X | C37: 驯兽 | H37: > | I37: =$G$16+F37+IF(B37="O",$AC$3,(IF(B37="❂",$AC$3*2,IF(B37="〄",INT($AC$3/2),0)))) -> 1 | L37: 手部 | N37: > | O37: 戒指 | T37: X | AD37: 法术DC | AI37: =施法!O2 -> 14 | AM37: 2 | AO37: =施法!AX6 -> 0 | AQ37: / | AR37: =施法!BA6 -> 0 | AV37: 物品同调 | AZ37: 0 | BC37: / | BE37: 3
B38: X | C38: 医药 | H38: > | I38: =$G$16+F38+IF(B38="O",$AC$3,(IF(B38="❂",$AC$3*2,IF(B38="〄",INT($AC$3/2),0)))) -> 1 | L38: 腰部 | N38: > | T38: X | AM38: 3 | AO38: =施法!AX7 -> 0 | AQ38: / | AR38: =施法!BA7 -> 0 | AV38: 激励 | AZ38: 0 | BC38: / | BE38: 1
B39: X | C39: 求生 | H39: > | I39: =$G$16+F39+IF(B39="O",$AC$3,(IF(B39="❂",$AC$3*2,IF(B39="〄",INT($AC$3/2),0)))) -> 1 | L39: 腿部 | N39: > | O39: 飞行靴 | T39: X | AM39: 4 | AO39: =施法!AX8 -> 0 | AQ39: / | AR39: =施法!BA8 -> 0 | AV39: 伤患
B40: 魅力系 | L40: 脚部 | N40: > | T40: X | AD40: 铂金币 | AM40: 5 | AO40: =施法!AX9 -> 0 | AQ40: / | AR40: =施法!BA9 -> 0 | AV40: 声望
B41: X | C41: 游说 | H41: > | I41: =$G$18+F41+IF(B41="O",$AC$3,(IF(B41="❂",$AC$3*2,IF(B41="〄",INT($AC$3/2),0)))) -> 3 | L41: 装备 | O41: =背包!B3 -> 速查 | R41: =背包!Y3 -> 自述 | U41: 总负重 | W41: 总财富 | Z41: 钱包 | AD41: 银金币 | AM41: 6 | AO41: =施法!AX10 -> 0 | AQ41: / | AR41: =施法!BA10 -> 0 | AV41: 献力
...

Sheet 背包
A1: 背包 Backpack
B3: 速查 | V3: =SUM(AX16:AX25,AX5:AX14) -> 0 | Y3: 自述 | AS3: =SUM(AY5:AY14,AY16:AY25) -> 0
B4: 名称 | I4: 描述 | S4: 磅 | V4: 数量 | Y4: 名称 | AF4: 描述 | AP4: 磅 | AS4: 数量
S5: =图表!AE145 -> 0 | U5: x | AR5: x | AX5: =S5*V5 -> 0 | AY5: =AP5*AS5 -> 0
S6: =图表!AE146 -> 0 | U6: x | AR6: x | AX6: =S6*V6 -> 0 | AY6: =AP6*AS6 -> 0
S7: =图表!AE147 -> 0 | U7: x | AR7: x | AX7: =S7*V7 -> 0 | AY7: =AP7*AS7 -> 0
S8: =图表!AE148 -> 0 | U8: x | AR8: x | AX8: =S8*V8 -> 0 | AY8: =AP8*AS8 -> 0
S9: =图表!AE149 -> 0 | U9: x | AR9: x | AX9: =S9*V9 -> 0 | AY9: =AP9*AS9 -> 0
S10: =图表!AE150 -> 0 | U10: x | AR10: x | AX10: =S10*V10 -> 0 | AY10: =AP10*AS10 -> 0
S11: =图表!AE151 -> 0 | U11: x | AR11: x | AX11: =S11*V11 -> 0 | AY11: =AP11*AS11 -> 0
S12: =图表!AE152 -> 0 | U12: x | AR12: x | AX12: =S12*V12 -> 0 | AY12: =AP12*AS12 -> 0
S13: =图表!AE153 -> 0 | U13: x | AR13: x | AX13: =S13*V13 -> 0 | AY13: =AP13*AS13 -> 0
S14: =图表!AE154 -> 0 | U14: x | AR14: x | AX14: =S14*V14 -> 0 | AY14: =AP14*AS14 -> 0
S16: =图表!AE156 -> 0 | U16: x | AR16: x | AX16: =S16*V16 -> 0 | AY16: =AP16*AS16 -> 0
S17: =图表!AE157 -> 0 | U17: x | AR17: x | AX17: =S17*V17 -> 0 | AY17: =AP17*AS17 -> 0
... S25: =图表!AE165 -> 0 | U25: x | AR25: x | AX25: =S25*V25 -> 0 | AY25: =AP25*AS25 -> 0
B27: 次元袋/载具 | V27: 有 | Y27: 账本笔记
B28: 名称 | I28: 描述 | S28: 磅 | V28: 数量
U29: x | BF29: =S29*V29 -> 0
U30: x | BF30: =S30*V30 -> 0
U31: x | BF31: =S31*V31 -> 0
U32: x | BF32: =S32*V32 -> 0
U33: x | BF33: =S33*V33 -> 0
U34: x | BF34: =S34*V34 -> 0
U35: x | BF35: =S35*V35 -> 0
U36: x | BF36: =S36*V36 -> 0
U37: x | BF37: =S37*V37 -> 0
U38: x | BF38: =S38*V38 -> 0
A39: .
U40: x | BF40: =S40*V40 -> 0
U41: x | BF41: =S41*V41 -> 0
U42: x | BF42: =S42*V42 -> 0
U43: x | BF43: =S43*V43 -> 0
U44: x | BF44: =S44*V44 -> 0
U45: x | BF45: =S45*V45 -> 0
U46: x | BF46: =S46*V46 -> 0
U47: x | BF47: =S47*V47 -> 0
U48: x | BF48: =S48*V48 -> 0
U49: x | BF49: =S49*V49 -> 0
B51: 次元袋/载具重量 | P51: 次元袋/载具负重（收纳） | U51: =SUM(BF29:BF38,BF40:BF49,BF54:BF63) -> 0

Sheet 施法
A1: 施法 Spellcasting
D2: 关键属性 | H2: 魅力 | K2: 法术豁免DC | O2: =SUM(8+主要情况!AC3+IF(H2="力量",主要情况!G8,IF(H2="敏捷",主要情况!G10,IF(H2="体质",主要情况!G12,IF(H2="智力",主要情况!G14,IF(H2="感知",主要情况!G16,IF(H2="魅力",主要情况!G18,0)))))))+BB17 -> 14 | R2: 法术命中 | V2: =(O2-BB17)-8+BB18 -> 6 | Y2: 已知戏法 | AC2: =图表!D61 -> 3 | AF2: 主职业已知法术 | AI2: =图表!E61 -> 6 | AK2: 主职业可准备法术数量 | AP2: =图表!F28 -> ∞
A3: 列表0 | D3: LV | E3: 学派 | H3: 仪式 | J3: 法术名 | P3: 施法时间 | R3: 施法距离 | U3: 持续时间 | AA3: V | AB3: S | AC3: M | AD3: 具体施法材料 | AL3: 法术效果 | AV3: 环阶 | AX3: 法术位 | BC3: 法术值消耗
B4: 准备 | C4: ╳ | D4: =法术大全!C561 -> 0 | E4: =法术大全!D561 -> 塑能 | H4: =法术大全!E561 -> x | J4: 魔能爆 | O4: > | P4: =法术大全!F561 -> 1动作 | R4: =法术大全!G561 -> 120尺 | U4: =法术大全!L561 -> 立即 | Z4: > | AA4: =法术大全!H561 -> V | AB4: =法术大全!I561 -> S | AC4: =法术大全!J561 -> × | AD4: =法术大全!K561 -> × | AK4: > | AV4: 0 | AX4: ∞ | AZ4: / | BA4: ∞ | BC4: 0
B5: 准备 | C5: ╳ | D5: =法术大全!C562 -> 0 | E5: =法术大全!D562 -> 幻术 | H5: =法术大全!E562 -> x | J5: 次级幻影 | O5: > | P5: =法术大全!F562 -> 1动作 | R5: =法术大全!G562 -> 30尺 | U5: =法术大全!L562 -> 1分钟 | Z5: > | AA5: =法术大全!H562 -> × | AB5: =法术大全!I562 -> S | AC5: =法术大全!J562 -> M | AD5: =法术大全!K562 -> 一小块羊毛 | AK5: > | AV5: 1 | AX5: 0 | AZ5: / | BA5: 0 | BC5: 2
B6: 准备 | C6: ╳ | D6: =法术大全!C563 -> 0 | E6: =法术大全!D563 -> 咒法 | H6: =法术大全!E563 -> x | J6: 法师之手 | O6: > | P6: =法术大全!F563 -> 1动作 | R6: =法术大全!G563 -> 30尺 | U6: =法术大全!L563 -> 1分钟 | Z6: > | AA6: =法术大全!H563 -> V | AB6: =法术大全!I563 -> S | AC6: =法术大全!J563 -> × | AD6: =法术大全!K563 -> × | AK6: > | AV6: 2 | AX6: 0 | AZ6: / | BA6: 0 | BC6: 3
B7: 准备 | C7: ╳ | D7: =法术大全!C564 -> 2 | E7: =法术大全!D564 -> 咒法 | H7: =法术大全!E564 -> x | J7: 迷踪步 | O7: > | P7: =法术大全!F564 -> 1附赠动作 | R7: =法术大全!G564 -> 自身 | U7: =法术大全!L564 -> 立即 | Z7: > | AA7: =法术大全!H564 -> V | AB7: =法术大全!I564 -> × | AC7: =法术大全!J564 -> × | AD7: =法术大全!K564 -> × | AK7: > | AV7: 3 | AX7: 0 | AZ7: / | BA7: 0 | BC7: 5
B8: 准备 | C8: ╳ | D8: =法术大全!C565 -> 2 | E8: =法术大全!D565 -> 惑控 | H8: =法术大全!E565 -> x | J8: 暗示术 | O8: > | P8: =法术大全!F565 -> 1动作 | R8: =法术大全!G565 -> 30尺 | U8: =法术大全!L565 -> 专注,至多8小时 | Z8: > | AA8: =法术大全!H565 -> V | AB8: =法术大全!I565 -> × | AC8: =法术大全!J565 -> M | AD8: =法术大全!K565 -> 一条蛇舌，加上一小块蜂巢或一滴甜油 | AK8: > | AV8: 4 | AX8: 0 | AZ8: / | BA8: 0 | BC8: 6
B9: 准备 | C9: ╳ | D9: =法术大全!C566 -> 2 | E9: =法术大全!D566 -> 幻术 | H9: =法术大全!E566 -> x | J9: 隐形术 | O9: > | P9: =法术大全!F566 -> 1动作 | R9: =法术大全!G566 -> 触及 | U9: =法术大全!L566 -> 专注,至多1小时 | Z9: > | AA9: =法术大全!H566 -> V | AB9: =法术大全!I566 -> S | AC9: =法术大全!J566 -> M | AD9: =法术大全!K566 -> 一根包裹在阿拉伯胶中的睫毛 | AK9: > | AV9: 5 | AX9: 0 | AZ9: / | BA9: 0 | BC9: 7
B10: 准备 | C10: ╳ | D10: =法术大全!C567 -> 2 | E10: =法术大全!D567 -> 惑控 | H10: =法术大全!E567 -> x | J10: 人类定身术 | O10: > | P10: =法术大全!F567 -> 1动作 | R10: =法术大全!G567 -> 60尺 | U10: =法术大全!L567 -> 专注,至多1分钟 | Z10: > | AA10: =法术大全!H567 -> V | AB10: =法术大全!I567 -> S | AC10: =法术大全!J567 -> M | AD10: =法术大全!K567 -> 一片直的小铁片 | AK10: > | AV10: 6 | AX10: 0 | AZ10: / | BA10: 0 | BC10: 9
B11: 准备 | C11: ╳ | D11: =法术大全!C568 -> 1 | E11: =法术大全!D568 -> 咒法 | H11: =法术大全!E568 -> √ | J11: 隐形仆役 | O11: > | P11: =法术大全!F568 -> 1动作 | R11: =法术大全!G568 -> 60尺 | U11: =法术大全!L568 -> 1小时 | Z11: > | AA11: =法术大全!H568 -> V | AB11: =法术大全!I568 -> S | AC11: =法术大全!J568 -> M | AD11: =法术大全!K568 -> 一根线和一块木头 | AK11: > | AV11: 7 | AX11: 0 | AZ11: / | BA11: 0 | BC11: 10
B12: 准备 | C12: ╳ | D12: =法术大全!C569 -> 0 | E12: =法术大全!D569 -> 变化 | H12: =法术大全!E569 -> x | J12: 修复术 | O12: > | P12: =法术大全!F569 -> 1分钟 | R12: =法术大全!G569 -> 触及 | U12: =法术大全!L569 -> 立即 | Z12: > | AA12: =法术大全!H569 -> V | AB12: =法术大全!I569 -> S | AC12: =法术大全!J569 -> M | AD12: =法术大全!K569 -> 两块天然磁石 | AK12: > | AV12: 8 | AX12: 0 | AZ12: / | BA12: 0 | BC12: 11
B13: 准备 | C13: ╳ | D13: 3 | E13: =法术大全!D570 -> #N/A | H13: =法术大全!E570 -> #N/A | J13: 亡灵召唤术 | O13: > | P13: =法术大全!F570 -> #N/A | R13: =法术大全!G570 -> #N/A | U13: =法术大全!L570 -> #N/A | Z13: > | AA13: =法术大全!H570 -> #N/A | AB13: =法术大全!I570 -> #N/A | AC13: =法术大全!J570 -> #N/A | AD13: =法术大全!K570 -> #N/A | AK13: > | AV13: 9 | AX13: 0 | AZ13: / | BA13: 0 | BC13: 13
A14: 列表1 | D14: LV | E14: 学派 | H14: 仪式 | J14: 法术名 | P14: 施法时间 | R14: 施法距离 | U14: 持续时间 | AA14: V | AB14: S | AC14: M | AD14: 具体施法材料 | AL14: 法术效果 | AV14: 环位合计法术值 | BE14: =SUM((BA5*2),(BA6*3),(BA7*5),(BA8*6),(BA9*7),(BA10*9),(BA11*10),(BA12*11),(BA13*13)) -> 0
B15: 准备 | C15: ╳ | D15: =法术大全!C572 -> - | E15: =法术大全!D572 -> - | H15: =法术大全!E572 -> - | O15: > | P15: =法术大全!F572 -> - | R15: =法术大全!G572 -> - | U15: =法术大全!L572 -> - | Z15: > | AA15: =法术大全!H572 -> - | AB15: =法术大全!I572 -> - | AC15: =法术大全!J572 -> - | AD15: =法术大全!K572 -> - | AK15: >
B16: 准备 | C16: ╳ | D16: =法术大全!C573 -> - | E16: =法术大全!D573 -> - | H16: =法术大全!E573 -> - | O16: > | P16: =法术大全!F573 -> - | R16: =法术大全!G573 -> - | U16: =法术大全!L573 -> - | Z16: > | AA16: =法术大全!H573 -> - | AB16: =法术大全!I573 -> - | AC16: =法术大全!J573 -> - | AD16: =法术大全!K573 -> - | AK16: > | AV16: 额外法术加值
B17: 准备 | C17: ╳ | D17: =法术大全!C574 -> - | E17: =法术大全!D574 -> - | H17: =法术大全!E574 -> - | O17: > | P17: =法术大全!F574 -> - | R17: =法术大全!G574 -> - | U17: =法术大全!L574 -> - | Z17: > | AA17: =法术大全!H574 -> - | AB17: =法术大全!I574 -> - | AC17: =法术大全!J574 -> - | AD17: =法术大全!K574 -> - | AK17: > | AV17: DC加值
B18: 准备 | C18: ╳ | D18: =法术大全!C575 -> - | E18: =法术大全!D575 -> - | H18: =法术大全!E575 -> - | O18: > | P18: =法术大全!F575 -> - | R18: =法术大全!G575 -> - | U18: =法术大全!L575 -> - | Z18: > | AA18: =法术大全!H575 -> - | AB18: =法术大全!I575 -> - | AC18: =法术大全!J575 -> - | AD18: =法术大全!K575 -> - | AK18: > | AV18: 命中加值
B19: 准备 | C19: ╳ | D19: =法术大全!C576 -> - | E19: =法术大全!D576 -> - | H19: =法术大全!E576 -> - | O19: > | P19: =法术大全!F576 -> - | R19: =法术大全!G576 -> - | U19: =法术大全!L576 -> - | Z19: > | AA19: =法术大全!H576 -> - | AB19: =法术大全!I576 -> - | AC19: =法术大全!J576 -> - | AD19: =法术大全!K576 -> - | AK19: >
B20: 准备 | C20: ╳ | D20: =法术大全!C577 -> - | E20: =法术大全!D577 -> - | H20: =法术大全!E577 -> - | O20: > | P20: =法术大全!F577 -> - | R20: =法术大全!G577 -> - | U20: =法术大全!L577 -> - | Z20: > | AA20: =法术大全!H577 -> - | AB20: =法术大全!I577 -> - | AC20: =法术大全!J577 -> - | AD20: =法术大全!K577 -> - | AK20: > | AV20: 等级 | AX20: 法术值 | BB20: 最大法术环阶
B21: 准备 | C21: ╳ | D21: =法术大全!C578 -> - | E21: =法术大全!D578 -> - | H21: =法术大全!E578 -> - | O21: > | P21: =法术大全!F578 -> - | R21: =法术大全!G578 -> - | U21: =法术大全!L578 -> - | Z21: > | AA21: =法术大全!H578 -> - | AB21: =法术大全!I578 -> - | AC21: =法术大全!J578 -> - | AD21: =法术大全!K578 -> - | AK21: > | AV21: 0 | AX21: 0 | BB21: 0
B22: 准备 | C22: ╳ | D22: =法术大全!C579 -> - | E22: =法术大全!D579 -> - | H22: =法术大全!E579 -> - | O22: > | P22: =法术大全!F579 -> - | R22: =法术大全!G579 -> - | U22: =法术大全!L579 -> - | Z22: > | AA22: =法术大全!H579 -> - | AB22: =法术大全!I579 -> - | AC22: =法术大全!J579 -> - | AD22: =法术大全!K579 -> - | AK22: > | AV22: 1 | AX22: 4 | BB22: 1
B23: 准备 | C23: ╳ | D23: =法术大全!C580 -> - | E23: =法术大全!D580 -> - | H23: =法术大全!E580 -> - | O23: > | P23: =法术大全!F580 -> - | R23: =法术大全!G580 -> - | U23: =法术大全!L580 -> - | Z23: > | AA23: =法术大全!H580 -> - | AB23: =法术大全!I580 -> - | AC23: =法术大全!J580 -> - | AD23: =法术大全!K580 -> - | AK23: > | AV23: 2 | AX23: 6 | BB23: 1
B24: 准备 | C24: ╳ | D24: =法术大全!C581 -> - | E24: =法术大全!D581 -> - | H24: =法术大全!E581 -> - | O24: > | P24: =法术大全!F581 -> - | R24: =法术大全!G581 -> - | U24: =法术大全!L581 -> - | Z24: > | AA24: =法术大全!H581 -> - | AB24: =法术大全!I581 -> - | AC24: =法术大全!J581 -> - | AD24: =法术大全!K581 -> - | AK24: > | AV24: 3 | AX24: 14 | BB24: 2
A25: 列表2 | D25: LV | E25: 学派 | H25: 仪式 | J25: 法术名 | P25: 施法时间 | R25: 施法距离 | U25: 持续时间 | AA25: V | AB25: S | AC25: M | AD25: 具体施法材料 | AL25: 法术效果 | AV25: 4 | AX25: 17 | BB25: 2
B26: 准备 | C26: ╳ | D26: =法术大全!C583 -> - | E26: =法术大全!D583 -> - | H26: =法术大全!E583 -> - | O26: > | P26: =法术大全!F583 -> - | R26: =法术大全!G583 -> - | U26: =法术大全!L583 -> - | Z26: > | AA26: =法术大全!H583 -> - | AB26: =法术大全!I583 -> - | AC26: =法术大全!J583 -> - | AD26: =法术大全!K583 -> - | AK26: > | AV26: 5 | AX26: 27 | BB26: 3
B27: 准备 | C27: ╳ | D27: =法术大全!C584 -> - | E27: =法术大全!D584 -> - | H27: =法术大全!E584 -> - | O27: > | P27: =法术大全!F584 -> - | R27: =法术大全!G584 -> - | U27: =法术大全!L584 -> - | Z27: > | AA27: =法术大全!H584 -> - | AB27: =法术大全!I584 -> - | AC27: =法术大全!J584 -> - | AD27: =法术大全!K584 -> - | AK27: > | AV27: 6 | AX27: 32 | BB27: 3
B28: 准备 | C28: ╳ | D28: =法术大全!C585 -> - | E28: =法术大全!D585 -> - | H28: =法术大全!E585 -> - | O28: > | P28: =法术大全!F585 -> - | R28: =法术大全!G585 -> - | U28: =法术大全!L585 -> - | Z28: > | AA28: =法术大全!H585 -> - | AB28: =法术大全!I585 -> - | AC28: =法术大全!J585 -> - | AD28: =法术大全!K585 -> - | AK28: > | AV28: 7 | AX28: 38 | BB28: 4
B29: 准备 | C29: ╳ | D29: =法术大全!C586 -> - | E29: =法术大全!D586 -> - | H29: =法术大全!E586 -> - | O29: > | P29: =法术大全!F586 -> - | R29: =法术大全!G586 -> - | U29: =法术大全!L586 -> - | Z29: > | AA29: =法术大全!H586 -> - | AB29: =法术大全!I586 -> - | AC29: =法术大全!J586 -> - | AD29: =法术大全!K586 -> - | AK29: > | AV29: 8 | AX29: 44 | BB29: 4
B30: 准备 | C30: ╳ | D30: =法术大全!C587 -> - | E30: =法术大全!D587 -> - | H30: =法术大全!E587 -> - | O30: > | P30: =法术大全!F587 -> - | R30: =法术大全!G587 -> - | U30: =法术大全!L587 -> - | Z30: > | AA30: =法术大全!H587 -> - | AB30: =法术大全!I587 -> - | AC30: =法术大全!J587 -> - | AD30: =法术大全!K587 -> - | AK30: > | AV30: 9 | AX30: 57 | BB30: 5
B31: 准备 | C31: ╳ | D31: =法术大全!C588 -> - | E31: =法术大全!D588 -> - | H31: =法术大全!E588 -> - | O31: > | P31: =法术大全!F588 -> - | R31: =法术大全!G588 -> - | U31: =法术大全!L588 -> - | Z31: > | AA31: =法术大全!H588 -> - | AB31: =法术大全!I588 -> - | AC31: =法术大全!J588 -> - | AD31: =法术大全!K588 -> - | AK31: > | AV31: 10 | AX31: 64 | BB31: 5
B32: 准备 | C32: ╳ | D32: =法术大全!C589 -> - | E32: =法术大全!D589 -> - | H32: =法术大全!E589 -> - | O32: > | P32: =法术大全!F589 -> - | R32: =法术大全!G589 -> - | U32: =法术大全!L589 -> - | Z32: > | AA32: =法术大全!H589 -> - | AB32: =法术大全!I589 -> - | AC32: =法术大全!J589 -> - | AD32: =法术大全!K589 -> - | AK32: > | AV32: 11 | AX32: 73 | BB32: 6
B33: 准备 | C33: ╳ | D33: =法术大全!C590 -> - | E33: =法术大全!D590 -> - | H33: =法术大全!E590 -> - | O33: > | P33: =法术大全!F590 -> - | R33: =法术大全!G590 -> - | U33: =法术大全!L590 -> - | Z33: > | AA33: =法术大全!H590 -> - | AB33: =法术大全!I590 -> - | AC33: =法术大全!J590 -> - | AD33: =法术大全!K590 -> - | AK33: > | AV33: 12 | AX33: 73 | BB33: 6
B34: 准备 | C34: ╳ | D34: =法术大全!C591 -> - | E34: =法术大全!D591 -> - | H34: =法术大全!E591 -> - | O34: > | P34: =法术大全!F591 -> - | R34: =法术大全!G591 -> - | U34: =法术大全!L591 -> - | Z34: > | AA34: =法术大全!H591 -> - | AB34: =法术大全!I591 -> - | AC34: =法术大全!J591 -> - | AD34: =法术大全!K591 -> - | AK34: > | AV34: 13 | AX34: 83 | BB34: 7
B35: 准备 | C35: ╳ | D35: =法术大全!C592 -> - | E35: =法术大全!D592 -> - | H35: =法术大全!E592 -> - | O35: > | P35: =法术大全!F592 -> - | R35: =法术大全!G592 -> - | U35: =法术大全!L592 -> - | Z35: > | AA35: =法术大全!H592 -> - | AB35: =法术大全!I592 -> - | AC35: =法术大全!J592 -> - | AD35: =法术大全!K592 -> - | AK35: > | AV35: 14 | AX35: 83 | BB35: 7
A36: 列表3 | D36: LV | E36: 学派 | H36: 仪式 | J36: 法术名 | P36: 施法时间 | R36: 施法距离 | U36: 持续时间 | AA36: V | AB36: S | AC36: M | AD36: 具体施法材料 | AL36: 法术效果 | AV36: 15 | AX36: 94 | BB36: 8
B37: 准备 | C37: ╳ | D37: =法术大全!C594 -> - | E37: =法术大全!D594 -> - | H37: =法术大全!E594 -> - | O37: > | P37: =法术大全!F594 -> - | R37: =法术大全!G594 -> - | U37: =法术大全!L594 -> - | Z37: > | AA37: =法术大全!H594 -> - | AB37: =法术大全!I594 -> - | AC37: =法术大全!J594 -> - | AD37: =法术大全!K594 -> - | AK37: > | AV37: 16 | AX37: 94 | BB37: 8
B38: 准备 | C38: ╳ | D38: =法术大全!C595 -> - | E38: =法术大全!D595 -> - | H38: =法术大全!E595 -> - | O38: > | P38: =法术大全!F595 -> - | R38: =法术大全!G595 -> - | U38: =法术大全!L595 -> - | Z38: > | AA38: =法术大全!H595 -> - | AB38: =法术大全!I595 -> - | AC38: =法术大全!J595 -> - | AD38: =法术大全!K595 -> - | AK38: > | AV38: 17 | AX38: 107 | BB38: 9
B39: 准备 | C39: ╳ | D39: =法术大全!C596 -> - | E39: =法术大全!D596 -> - | H39: =法术大全!E596 -> - | O39: > | P39: =法术大全!F596 -> - | R39: =法术大全!G596 -> - | U39: =法术大全!L596 -> - | Z39: > | AA39: =法术大全!H596 -> - | AB39: =法术大全!I596 -> - | AC39: =法术大全!J596 -> - | AD39: =法术大全!K596 -> - | AK39: > | AV39: 18 | AX39: 114 | BB39: 9
B40: 准备 | C40: ╳ | D40: =法术大全!C597 -> - | E40: =法术大全!D597 -> - | H40: =法术大全!E597 -> - | O40: > | P40: =法术大全!F597 -> - | R40: =法术大全!G597 -> - | U40: =法术大全!L597 -> - | Z40: > | AA40: =法术大全!H597 -> - | AB40: =法术大全!I597 -> - | AC40: =法术大全!J597 -> - | AD40: =法术大全!K597 -> - | AK40: > | AV40: 19 | AX40: 123 | BB40: 9
...

Sheet 法术大全
A1: =施法!J3 -> 法术名 | B1: 法术名 | C1: 环阶 | D1: 学派 | E1: 仪式 | F1: 施法时间 | G1: 施法距离 | H1: V 言语 | I1: S 姿势 | J1: M 材料 | K1: 材料内容 | L1: 持续时间 | M1: 法术详述 | N1: 名字 | O1: 英文名 | P1: 吟游诗人 | Q1: 牧师 | R1: 德鲁伊 | S1: 圣武士 | T1: 游侠 | U1: 术士 | V1: 邪术师 | W1: 法师 | X1: 奇械师 | Y1: 时间法师 | Z1: 重力法师 | AA1: 出处
A2: =施法!J4 -> 魔能爆 | B2: 酸液飞溅 | C2: 0 | D2: 咒法 | E2: x | F2: 1动作 | G2: 60尺 | H2: V | I2: S | J2: × | K2: × | L2: 立即 | M2: ·你掷出一颗酸液球。在施法距离内指定一个生物，或者在距离内指定两个相距不超过5尺的生物。每个目标必须进行一次敏捷豁免，豁免失败则受到1d6点强酸伤害。 ·你到达5级时，该法术的伤害增加1d6（变为2d6）11级时再加1d6（变为3d6），17级时再加1d6（变为4d6）。 | N2: 酸液飞溅 | O2: Acid Splash | U2: √ | W2: √ | X2: √ | AA2: 玩家手册
A3: =施法!J5 -> 次级幻影 | B3: 剑刃防护 | C3: 0 | D3: 防护 | E3: x | F3: 1动作 | G3: 自身 | H3: V | I3: S | J3: × | K3: × | L3: 1轮 | M3: ·你伸手在空中勾勒出一个防护印记，以令自己在下一回合结束前对武器攻击造成的钝击、穿刺和挥砍伤害具有抗性。 | N3: 剑刃防护 | O3: Blade Ward | P3: √ | U3: √ | V3: √ | W3: √ | AA3: 玩家手册
A4: =施法!J6 -> 法师之手 | B4: 轰雷剑 | C4: 0 | D4: 塑能 | E4: x | F4: 1动作 | G4: 自身(5尺半径) | H4: × | I4: S | J4: M | K4: 一把至少价值1sp的近战武器 | L4: 1轮 | M4: ·作为施展该法术的一部分，你必须用你的武器对5尺内的一个生物进行一次近战攻击。如果攻击命中，目标受到这次攻击的正常影响，并且被包覆在爆发性的能量之中，直到你下回合开始前。如果目标在结束之前自愿移动了5尺或更多，其立即受到1d8点雷鸣伤害，并且法术结束。 ·该法术的伤害随着你的等级提升而增加。你到达5级时，这次近战攻击将造成额外1d8点雷鸣伤害，并且目标进行移动时受到的伤害提升为2d8。两个伤害骰都会在11级时增加1d8（2d8和3d8），17级时再加1d8（3d8和4d8）。 | N4: 轰雷剑 | O4: Booming Blade | U4: √ | V4: √ | W4: √ | X4: √ | AA4: 剑湾冒险者指南
A5: =施法!J7 -> 迷踪步 | B5: 冻寒之触 | C5: 0 | D5: 死灵 | E5: x | F5: 1动作 | G5: 120尺 | H5: V | I5: S | J5: × | K5: × | L5: 1轮 | M5: ·你在施法距离内某生物所在位置召唤出幽魂般的骨手，夹带着墓穴的刺骨冻寒攻击目标。并对该生物进行一次远程法术攻击，命中时，手掌抓住目标并令其受1d8点黯蚀伤害，且直至你下一回合开始前都无法恢复生命值。 ·如果你的命中目标为一个不死生物，则其在你下回合结束之前对你发动的攻击检定都具有劣势。 ·你到达5级时，该法术的伤害增加1d8（变为2d8）。11级时再加1d8（变为3d8），17级时再加1d8（变为4d8）。 | N5: 冻寒之触 | O5: Chill Touch | U5: √ | V5: √ | W5: √ | AA5: 玩家手册
A6: =施法!J8 -> 暗示术 | B6: 控火 | C6: 0 | D6: 变化 | E6: x | F6: 1动作 | G6: 60尺 | H6: × | I6: S | J6: × | K6: × | L6: 立即或1小时 | M6: ·你选择范围内你能看见的，占据5立方尺的非魔法火焰。你以下述方式之一影响此火焰： ·你立刻令火焰在一个方向上蔓延5尺，如同在新位置处有着木头或其他燃料。 ·你立刻熄灭该空间内的火焰。 、 ·你令火焰产生的明亮和微亮区域的范围加倍或减半，和/或改变其颜色。此种变化持续1个小时。 ·你令火焰产生简单的形象——例如一个生物的模糊影像，一个固定的物体，或一个地点——这样的影像出现在火焰中，如你所愿变化着。这样的形象持续1个小时 ·若你多次施放此法术，你可以令至多3个非立刻的效应同时生效，而你可以以一个动作解除上述的效果之一。 | N6: 控火 | O6: Control Flames | R6: √ | U6: √ | W6: √ | AA6: 珊娜萨的万事指南
A7: =施法!J9 -> 隐形术 | B7: 创造篝火 | C7: 0 | D7: 咒法 | E7: x | F7: 1动作 | G7: 60尺 | H7: V | I7: S | J7: × | K7: × | L7: 专注,至多1分钟 | M7: ·你在距离之内你能看到的地面上燃起一堆篝火。直到此法术终结，该魔法篝火会占满5立方尺的空间。当你施放此法术时，所有在篝火所在空间的生物必须通过一次敏捷豁免，否则受到1d8点伤害。当生物在一个回合中第一次进入篝火所在的空间，或在篝火所在的空间结束其回合时，其同样必须进行该豁免。 ·篝火可以点燃区域内未被穿戴或者携带的可燃物体。 ·你到达5级时，该法术的伤害增加1d8（变为2d8）。11级时再加1d8（变为3d8），17级时再加1d8（变为4d8）。 | N7: 创造篝火 | O7: Create Bonfire | R7: √ | U7: √ | V7: √ | W7: √ | X7: √ | AA7: 珊娜萨的万事指南
A8: =施法!J10 -> 人类定身术 | B8: 舞光术 | C8: 0 | D8: 塑能 | E8: x | F8: 1动作 | G8: 120尺 | H8: V | I8: S | J8: M | K8: 一点磷或光榆木，或者一只萤火虫 | L8: 专注,至多1分钟 | M8: ·你在施法距离内创造四个火把大小的光源。法术持续时间内，光源能够以火把，灯笼或光球的形态显现并在空中悬浮。你也可以将四个光源合为一个中型类人生物的模糊光影。无论选择哪种方式，每处光源都可以发出半径10尺的微光光照。 ·你在自己回合可以用一个附赠动作令这些光源在施法距离内移动至多60尺。每个光源必需在另一个光源周边20尺内，而离开施法距离的光源会随即熄灭。 | N8: 舞光术 | O8: Dancing Lights | P8: √ | U8: √ | W8: √ | X8: √ | AA8: 玩家手册
A9: =施法!J11 -> 隐形仆役 | B9: 德鲁伊伎俩 | C9: 0 | D9: 变化 | E9: x | F9: 1动作 | G9: 30尺 | H9: V | I9: S | J9: × | K9: × | L9: 立即 | M9: ·你向自然之魂低语，并创造以下效应之一： →你创造一个微小而无害的感官效应，并以之预报你所在地接下来24小时的天气状况。该效应可表现为一个代表晴空的金球，一朵代表雨天的云彩，代表雪日而飘飞的雪花等等。该效应将持续1轮。 →你可以立即让一朵鲜花绽放，一颗种子破壳，一片叶蕾发芽。 →你创造一个微小而无害的即时感官效应，如落叶，微风，小动物的动静或者臭鼬的微弱气味。该效应只能在5尺的立方空间内起效。 →你可以立即点亮或熄灭一根蜡烛、一把火把或一处小篝火。 | N9: 德鲁伊伎俩 | O9: Druidcraft | R9: √ | AA9: 玩家手册
A10: =施法!J12 -> 修复术 | B10: 魔能爆 | C10: 0 | D10: 塑能 | E10: x | F10: 1动作 | G10: 120尺 | H10: V | I10: S | J10: × | K10: × | L10: 立即 | M10: ·一束激烈的能量射向施法距离内一个生物。对该目标发动一次远程法术攻击，如果命中则该目标受1d10点力场伤害。 ·当你到达更高等级时，该法术还可以同时创造更多的射线：5级时两条，11级时三条，17级时四条。你可以决定这些射线攻击同一个目标或分别攻击不同的目标，且为每束射线分别进行攻击检定。 | N10: 魔能爆 | O10: Eldritch Blast | V10: √ | AA10: 玩家手册
A11: =施法!J13 -> 亡灵召唤术 | B11: 火焰箭 | C11: 0 | D11: 塑能 | E11: x | F11: 1动作 | G11: 120尺 | H11: V | I11: S | J11: × | K11: × | L11: 立即 | M11: ·你对施法距离内一个生物或物件掷出一把火焰，对目标进行一次远程法术攻击。若命中，则目标受到1d10点火焰伤害。未被着装或携带的可燃物件被该法术命中时将被点燃。 ·你到达5级时，该法术的伤害增加1d10（变为2d10）。11级时再加1d10（变为3d10），17级时再加1d10（变为4d10）。 | N11: 火焰箭 | O11: Fire Bolt | U11: √ | W11: √ | X11: √ | AA11: 玩家手册
A12: =施法!J14 -> 法术名 | B12: 交友术 | C12: 0 | D12: 惑控 | E12: x | F12: 1动作 | G12: 自身 | H12: × | I12: S | J12: M | K12: 法术施展时作用于脸部的一些化妆用品 | L12: 专注,至多1分钟 | M12: ·指定一个对你非敌对的生物，你在法术持续时间内对其进行的所有魅力检定均具有优势。当该法术终止时，该生物将意识到你曾使用魔法操弄他的情绪，从而对你的态度转为敌对。此时如果该生物有暴力倾向则会直接对你发动攻击，而非暴力倾向的生物则会寻求其他的报复形式（由DM决定），具体情况视你与其交互时的具体内容而定。 | N12: 交友术 | O12: Friend | P12: √ | U12: √ | V12: √ | W12: √ | AA12: 玩家手册
A13: =施法!J15 -> 0 | B13: 霜噬 | C13: 0 | D13: 塑能 | E13: x | F13: 1动作 | G13: 60尺 | H13: V | I13: S | J13: × | K13: × | L13: 立即 | M13: ·你令距离之内，一个你能看见的生物开始结冰。该目标必须进行一次体质豁免检定。若豁免失败，该目标受到1d6点冷冻伤害，并在其下个回合结束前进行的下一次武器攻击检定中得到劣势。 ·你到达5级时，该法术的伤害增加1d6（变为2d6）。11级时再加1d6（变为3d6），17级时再加1d6（变为4d6）。 | N13: 霜噬 | O13: Frostbite | R13: √ | U13: √ | V13: √ | W13: √ | X13: √ | AA13: 珊娜萨的万事指南
A14: =施法!J16 -> 0 | B14: 翠炎剑 | C14: 0 | D14: 塑能 | E14: x | F14: 1动作 | G14: 自身(5尺半径) | H14: × | I14: S | J14: M | K14: 一把至少价值1sp的近战武器 | L14: 立即 | M14: ·作为施展该法术的一部分，你必须用你的武器对5尺内的一个生物进行一次近战攻击。如果攻击命中，目标受到这次攻击的正常影响，并且翠绿色的火焰将从目标身上跳转至其5尺内的另一个生物。第二个生物受到等于你施法关键属性调整值点火焰伤害。 ·该法术的伤害随着你的等级提升而增加。你到达5级时，这次近战攻击将造成额外1d8火焰伤害，且第二个目标将受到的伤害提升至1d8+你的施法关键属性调整值。两个伤害骰都会在11级时增加1d8（2d8和2d8），17级时再加1d8（3d8和3d8）。 | N14: 翠炎剑 | O14: Green Flame Blade | U14: √ | V14: √ | W14: √ | X14: √ | AA14: 剑湾冒险者指南
A15: =施法!J17 -> 0 | B15: 神导术 | C15: 0 | D15: 预言 | E15: x | F15: 1动作 | G15: 触及 | H15: V | I15: S | J15: × | K15: × | L15: 专注,至多1分钟 | M15: ·你触碰一个自愿的生物。在法术终止前，目标可以选择在一次属性检定时额外掷一粒d4，并将所得数值加入检定结果中。它可以在进行属性检定之前或之后掷骰。法术随后即终止。 | N15: 神导术 | O15: Guidance | Q15: √ | R15: √ | X15: √ | AA15: 玩家手册
A16: =施法!J18 -> 0 | B16: 舞风 | C16: 0 | D16: 变化 | E16: x | F16: 1动作 | G16: 30尺 | H16: V | I16: S | J16: × | K16: × | L16: 立即 | M16: ·在距离内的，你能看到的一点上，空气被你掌握，被迫产生了下述效应之一： ·由你选择的一个中型或更小的生物必须通过一次力量豁免，否则会被你推离5尺。 ·你能制造出小小的空气爆破，足以移动一个未被持握或携带的，不超过5磅的物体。该物体被推离你10尺。以此法产生的力不足以造成伤害。 ·你利用空气制造出无害的感官感受，例如令树叶沙沙作响，令百叶窗闭合，或你的衣服在微风中摆动。 | N16: 舞风 | O16: Gust | R16: √ | U16: √ | W16: √ | AA16: 珊娜萨的万事指南
A17: =施法!J19 -> 0 | B17: 虫群孳生 | C17: 0 | D17: 咒法 | E17: x | F17: 1动作 | G17: 30尺 | H17: V | I17: S | J17: M | K17: 一只活跳蚤 | L17: 立即 | M17: ·你令一个处于距离内、你能看见的生物身上暂时性的出现螨虫、跳蚤、和其他寄生虫。目标必须通过一次体质豁免，否则受到1d6点毒素伤害并且向着一个随机的方向移动5尺，只要它可以移动并且有至少5尺的速度。投1d4决定方向：1，北；2，南；3，东；4，西。这个移动不会提供借机攻击，并且如果移动的方向被阻挡，目标将不会移动。 ·此法术的伤害在你达到5级（2d6），11级（3d6），和17级（4d6）时提高1d6点。 | N17: 虫群孳生 | O17: Infestation | R17: √ | U17: √ | V17: √ | W17: √ | AA17: 珊娜萨的万事指南
A18: =施法!J20 -> 0 | B18: 光亮术 | C18: 0 | D18: 塑能 | E18: x | F18: 1动作 | G18: 触及 | H18: V | I18: × | J18: M | K18: 一只萤火虫或一片磷光苔藓 | L18: 1小时 | M18: ·你触碰一个尺寸在任意方向上都不超过10尺的物件。在法术终止前，物件将在其20尺半径范围内发出明亮光照，并在其外20尺范围发出微光光照。光的颜色由你决定，该物件被不透明的东西完全遮盖时，其光照被遮挡。如果你再次施展该法术，或者使用一个动作解散该法术，则该法术终止。 ·如果你指定敌对生物所持握或着装的一个物件作为目标，则该生物必须进行一次敏捷豁免以尝试摆脱该法术的效应。 | N18: 光亮术 | O18: Light | P18: √ | Q18: √ | U18: √ | W18: √ | X18: √ | AA18: 玩家手册
A19: =施法!J21 -> 0 | B19: 闪电牵引 | C19: 0 | D19: 塑能 | E19: x | F19: 1动作 | G19: 15尺 | H19: V | I19: × | J19: × | K19: × | L19: 立即 | M19: ·你创造出鞭状的闪电能量袭向你15尺内可见的一个生物。目标必须进行一次力量豁免，豁免失败则其以直线被你拉近10尺。如果拉近以后目标在你周围5尺内，那么他将受到1d8点闪电伤害。 ·你到达5级时，该法术的伤害增加1d8（变为2d8）。11级时再加1d8（变为3d8），17级时再加1d8（变为4d8）。 | N19: 闪电牵引 | O19: Lightning Lure | U19: √ | V19: √ | W19: √ | X19: √ | AA19: 剑湾冒险者指南
A20: =施法!J22 -> 0 | B20: 法师之手 | C20: 0 | D20: 咒法 | E20: x | F20: 1动作 | G20: 30尺 | H20: V | I20: S | J20: × | K20: × | L20: 1分钟 | M20: ·一只漂浮的幽灵手出现在施法距离内你指定的一点。幽灵手持续存在至法术终止，或直至你以一个动作解散该法术。如果幽灵手距你的距离超过30尺，或者当你再次施展了该法术时，则现存的幽灵手消失不见。 ·你可以用动作控制幽灵手，并通过幽灵手实现一个行为：你可以操控一个物件，或者打开一扇未上锁的门或容器，或者将一件物品放入容器或从容器中取出，或者将小瓶中的内容物倾倒出来。你每次你使用幽灵手时可以令其移动至多30尺。 ·该幽灵手不能攻击，也不能激活魔法物品或承载超过10磅重的物质。 | N20: 法师之手 | O20: Mage Hand | P20: √ | U20: √ | V20: √ | W20: √ | X20: √ | AA20: 玩家手册
A21: =施法!J23 -> 0 | B21: 魔石 | C21: 0 | D21: 变化 | E21: x | F21: 1附赠动作 | G21: 触及 | H21: V | I21: S | J21: × | K21: × | L21: 1分钟 | M21: ·你接触一到三块小石块，向其中注入魔法的力量。你或其他人可以通过徒手或使用投石索来投掷小石块之一以进行一次远程法术攻击。若徒手投掷，其射程为60尺。若除你之外的其他人使用小石块进行攻击，攻击者在其攻击检定中加上你的施法属性调整值，而非攻击者的。若击中，目标受到1d6+你的施法属性调整值点数点钝击伤害。无论击中与否，在那块石块上的魔法都会消失。 ·若你再次释放此法术，此法术先前释放时，在受到影响的石块上的效果会提前结束。 | N21: 魔石 | O21: Magic Stone | R21: √ | V21: √ | X21: √ | AA21: 珊娜萨的万事指南
A22: =施法!J24 -> 0 | B22: 修复术 | C22: 0 | D22: 变化 | E22: x | F22: 1分钟 | G22: 触及 | H22: V | I22: S | J22: M | K22: 两块天然磁石 | L22: 立即 | M22: ·该法术修复你所触碰一个物件上的一处破损或裂缝，例如修复一条断裂的链条，或者一把碎成两半的钥匙、一件撕裂的斗篷、一个漏了的酒袋等。只要破损或断裂处在任意方向上都不超过1尺，你就可以不留痕迹地修复它。 ·该法术可以从物理上修复一件魔法物品或一个构装体，但不会恢复这类物件上的魔法。 | N22: 修复术 | O22: Mending | P22: √ | Q22: √ | R22: √ | U22: √ | W22: √ | X22: √ | AA22: 玩家手册
A23: =施法!J25 -> 法术名 | B23: 传讯术 | C23: 0 | D23: 变化 | E23: x | F23: 1动作 | G23: 120尺 | H23: V | I23: S | J23: M | K23: 一小段铜线 | L23: 1轮 | M23: ·你用手指指向施法距离内的一个生物并低声说出一段信息。该目标（且只有该目标）会听到这段信息并可以用只有你能听见的低语回复你。 ·你可以隔着固态物件施展该法术，但你必须熟悉法术目标并知晓其就在屏障后方。魔法的沉默，1尺厚的石头，1寸厚的普通金属，一片薄铅片，或者3尺厚的木料都可以阻挡该法术。该法术不需要直线传递信息，它可以自由地转过拐角或穿过孔洞。 | N23: 传讯术 | O23: Message | P23: √ | U23: √ | W23: √ | X23: √ | AA23: 玩家手册
A24: =施法!J26 -> 0 | B24: 心灵之楔 | C24: 0 | D24: 惑控 | E24: x | F24: 1动作 | G24: 60尺 | H24: V | I24: × | J24: × | K24: × | L24: 1轮 | M24: ·你将由灵能塑成的迷惘尖刺打入一个距离内可见生物的心智。目标必须进行一次智力豁免，豁免失败则将受到1d6点心灵伤害，且在你下回合结束前进行的下一次豁免检定中，在结果上减去1d4。 ·这道法术的伤害在你达到特定等级时增加1d6：5级（变为2d6），11级（变为3d6），17级（变为4d6）。 | N24: 心灵之楔 | O24: Mind Sliver | U24: √ | V24: √ | W24: √ | AA24: 塔莎的万象坩埚
A25: =施法!J27 -> 0 | B25: 次级幻影 | C25: 0 | D25: 幻术 | E25: x | F25: 1动作 | G25: 30尺 | H25: × | I25: S | J25: M | K25: 一小块羊毛 | L25: 1分钟 | M25: ·你在施法距离内创造一段声响或一个物件的影像，并使之维持至法术持续时间结束。你也可以用一个动作解除幻象，或者再次施展该法术来终止幻象。 ·如果你创造一段声响，其音量可以是低声耳语也可以是高声尖叫。它可以是你或其他任何人的嗓音，或者是一头狮子的咆哮、一段鼓声以及任何你指定的其它声响。声响在持续时间内不会减弱，或者你也可以于法术终止前在不同的时间段创造几段分散的声响。 ·如果你创造一个物件的影像（比如一把椅子、泥泞的脚印、一个小箱子等），则该物件大小不得大于一个边长5尺的立方体。该影像不具有声音、光亮、味道或任何其他的感官效应。由于影像可以被任何物件所穿透，因此与之进行物理互动时都会揭露其幻象的本质。 ·生物用其动作调查该声响或影像时，必须进行一次对抗该法术豁免DC的智力（调查）检定，检定成功则判断出眼前即是幻象。幻象在看穿它的生物面前会显得模糊不清。 | N25: 次级幻影 | O25: Minor Illusion | P25: √ | U25: √ | V25: √ | W25: √ | AA25: 玩家手册
A26: =施法!J28 -> 0 | B26: 塑土 | C26: 0 | D26: 变化 | E26: x | F26: 1动作 | G26: 30尺 | H26: × | I26: S | J26: × | K26: × | L26: 立即或1小时 | M26: ·你选择距离之内，你能看见的，占满5立方尺空间的一堆泥土或一块岩石。你可以用以下方式之一对其进行改变： ·若你指向一片松散的土壤，你可以立刻挖开它，令其沿着地表行进，被运离到至多5尺之外的地方。这种移动的力量不足以造成伤害。 ·你让泥土或岩石的形状，和/或颜色发生改变，写出文字，画出图案或雕出图纹。这种变化持续1个小时。 ·若你指定的泥土或岩石在地表上，你可以令其成为困难地形。作为另一种选项，你亦可以令已经是困难地形的地表区域成为正常地形。这种变化持续1个小时。 ·若你多次施放此法术，你可以同时维持至多两个非立即的效果生效，你也可以以一个动作解消上述效应之一。 | N26: 塑土 | O26: Mold Earth | R26: √ | U26: √ | W26: √ | AA26: 珊娜萨的万事指南
A27: =施法!J29 -> 0 | B27: 毒气喷溅 | C27: 0 | D27: 咒法 | E27: x | F27: 1动作 | G27: 10尺 | H27: V | I27: S | J27: × | K27: × | L27: 立即 | M27: ·你伸手向施法距离内一个你能看见的生物喷一阵毒气。目标必须进行一次体质豁免，豁免失败则受1d12毒素伤害。 ·你到达5级时，该法术的伤害增加1d12（变为2d12）。11级时再加1d12（变为3d12），17级时再加1d12（变为4d12） | N27: 毒气喷溅 | O27: Poison Spray | R27: √ | U27: √ | V27: √ | W27: √ | X27: √ | AA27: 玩家手册
A28: =施法!J30 -> 0 | B28: 魔法伎俩 | C28: 0 | D28: 变化 | E28: x | F28: 1动作 | G28: 10尺 | H28: V | I28: S | J28: × | K28: × | L28: 至多1小时 | M28: ·该法术是一个初级施法者用来练习的魔法小伎俩。你在施法距离内创造下列魔法效果中的一种： →你创造一个立即生效的，无害的感观效应，比如一束火花，一阵风，微弱音乐或古怪的臭味。 →你立即点燃或熄灭一支蜡烛，一支火把或一小型营火。 →你立即使一个不大于1立方尺的物件变得清洁或肮脏。 →你立即使一个不大于1立方尺的非活体物质变得冰冷、温暖或对其调味，其效应持续1小时。 →你在一个物件或一个表面上创造一块色斑，或者一个记号，又或者一个标志，其效应持续1小时。 →你创造一个巴掌大小的非魔法小玩意或一个虚幻图像，其效应持续到你下回合结束。 ·如果你多次施展该法术，则可以同时维持至多三个不同的非即时效应，并且可以用一个动作解散其中一种效应。 | N28: 魔法伎俩 | O28: Prestidigitation | P28: √ | U28: √ | V28: √ | W28: √ | X28: √ | AA28: 玩家手册
A29: =施法!J31 -> 0 | B29: 原初蛮击 | C29: 0 | D29: 变化 | E29: x | F29: 1动作 | G29: 自身 | H29: × | I29: S | J29: × | K29: × | L29: 立即 | M29: ·你的牙齿或指甲变得长而尖锐，从而准备好发起酸蚀性的打击。对一个处于你周围5尺内的生物进行一次近战法术攻击。命中则目标受到1d10点强酸伤害。在你进行此攻击后，你的牙齿或指甲恢复正常。 ·此法术的伤害在你达到5级（2d10），11级（3d10），和17级（4d10）时提高1d10点。 | N29: 原初蛮击 | O29: Primal Savagery | R29: √ | AA29: 珊娜萨的万事指南
A30: =施法!J32 -> 0 | B30: 燃火术 | C30: 0 | D30: 咒法 | E30: x | F30: 1动作 | G30: 自身 | H30: V | I30: S | J30: × | K30: × | L30: 10分钟 | M30: ·一朵摇曳的火焰出现在你手中。火焰在法术持续时间存在，并且不会伤害你和你的装备。火焰为其周边半径10尺范围内提供明亮光照，以及该范围外10尺的微光光照。法术将在再次施展该法术，或者以一个动作解除法术时终止。 ·此外，你还可以使用火焰发动攻击，并以此终止该法术。施展该法术时，你可以将火焰投向距你30尺内的一个生物，并对其发动一次远程法术攻击，命中时目标将受到1d8点火焰伤害。你也可以在施展法术后的随后回合里以一个动作实现该行为。 ·你到达5级时，该法术的伤害增加1d8（变为2d8）。11级时再加1d8（变为3d8），17级时再加1d8（变为4d8）。 | N30: 燃火术 | O30: Produce Flame | R30: √ | AA30: 玩家手册
A31: =施法!J33 -> 0 | B31: 冷冻射线 | C31: 0 | D31: 塑能 | E31: x | F31: 1动作 | G31: 60尺 | H31: V | I31: S | J31: × | K31: × | L31: 立即 | M31: ·一道冰冷的蓝白色光线朝施法距离内的一个生物射去。你对目标进行一次远程法术攻击。若命中，则目标受到1d8点冷冻伤害，并且在你的下一回合开始前速度减少10尺。 ·你到达5级时，该法术的伤害增加1d8（变为2d8）。11级时再加1d8（变为3d8），17级时再加1d8（变为4d8）。 | N31: 冷冻射线 | O31: Ray of Frost | U31: √ | W31: √ | X31: √ | AA31: 玩家手册
A32: =施法!J34 -> 0 | B32: 提升抗性 | C32: 0 | D32: 防护 | E32: x | F32: 1动作 | G32: 触及 | H32: V | I32: S | J32: M | K32: 一件微型斗篷 | L32: 专注,至多1分钟 | M32: ·你触碰一个自愿的生物。在法术终止前，目标可以选择在一次豁免检定时额外掷一粒d4，并将所得数值加入检定结果中。他可以在进行豁免检定之前或之后掷骰。法术随后即终止。 | N32: 提升抗性 | O32: Resistance | Q32: √ | R32: √ | X32: √ | AA32: 玩家手册
A33: =施法!J35 -> 0 | B33: 圣火术 | C33: 0 | D33: 塑能 | E33: x | F33: 1动作 | G33: 60尺 | H33: V | I33: S | J33: × | K33: × | L33: 立即 | M33: ·如同火焰般的辉光向施法距离内你能看见的一个生物倾泻而下。目标必须要进行一次敏捷豁免，豁免失败则受到1d8点光耀伤害。目标在这次豁免检定中无法获得掩护的增益。 ·你到达5级时，该法术的伤害增加1d8（变为2d8）。11级时再加1d8（变为3d8），17级时再加1d8（变为4d8）。 | N33: 圣火术 | O33: Sacred Flame | Q33: √ | AA33: 玩家手册
A34: =施法!J36 -> 法术名 | B34: 削弱芒刺 | C34: 0 | D34: 死灵 | E34: x | F34: 1动作 | G34: 30尺 | H34: V | I34: S | J34: × | K34: × | L34: 立即 | M34: ·你削弱施法距离内一个你看得见的生物的生命活力。目标必须通过一个体质豁免，否则就会受到1d4点黯蚀伤害并且倒地。 ·该法术的伤害会在你到达5级（2d4），11级（3d4）与17级（4d4）时增加1d4. | N34: 削弱芒刺 | O34: Sapping Sting | Y34: √ | Z34: √ | AA34: 荒洲探险家指南
A35: =施法!J37 -> 0 | B35: 操水 | C35: 0 | D35: 变化 | E35: x | F35: 1动作 | G35: 30尺 | H35: × | I35: S | J35: × | K35: × | L35: 立即或1小时 | M35: ·你选定距离之内，你能看见的一处占据5立方尺的水体。你能以下述方式之一来对其进行操控： ·你立即在你选定的方向上，造成或改变水的流动，至多在任意方向上改变5尺。此种运动的力量不足以造成伤害。 ·你令水体呈现出简单的形状，随你的意愿而运动。这种变化持续1个小时。 ·你改变了水体的颜色或透明度。水体必须被整体性的改变。此种变化持续1个小时。 ·你冻结了水，只要其中没有生物。水会在1小时内解冻。 ·若你多次施放此法术，你可以同时维持至多两个非立即的效果生效，你也可以以一个动作解消上述效应之一。 | N35: 操水 | O35: Shape Water | R35: √ | U35: √ | W35: √ | AA35: 珊娜萨的万事指南
A36: =施法!J38 -> 0 | B36: 橡棍术 | C36: 0 | D36: 变化 | E36: x | F36: 1附赠动作 | G36: 触及 | H36: V | I36: S | J36: M | K36: 一些槲寄生，一片三叶草的叶子和一根短棒或木杖 | L36: 1分钟 | M36: ·你将自然之力灌入手中持握的一根短棒或木杖中。你在法术持续时间内使用该武器进行近战攻击时可以用你的施法关键属性代替力量值来进行攻击检定和伤害掷骰，且该武器的伤害骰变为d8。另外，如果该武器原来不是魔法武器，则它将变成魔法武器。你再次施展该法术或丢掉该武器时，该法术将随之终止。 | N36: 橡棍术 | O36: Shillelagh | R36: √ | AA36: 玩家手册
A37: =施法!J39 -> 0 | B37: 电爪 | C37: 0 | D37: 塑能 | E37: x | F37: 1动作 | G37: 触及 | H37: V | I37: S | J37: × | K37: × | L37: 立即 | M37: ·你的手上发出闪电，并对你触碰的一个生物发动电击。对目标发动一次近战法术攻击。如果目标穿着金属护甲，则你进行该检定时具有优势。若命中，则目标受到1d8点闪电伤害，并且在其下一回合开始前不能执行任何反应。 ·你到达5级时，该法术的伤害增加1d8（变为2d8）。11级时再加1d8（变为3d8），17级时再加1d8（变为4d8）。 | N37: 电爪 | O37: Shocking Grasp | U37: √ | W37: √ | X37: √ | AA37: 玩家手册
A38: =施法!J40 -> 0 | B38: 维生术 | C38: 0 | D38: 死灵 | E38: x | F38: 1动作 | G38: 触及 | H38: V | I38: S | J38: × | K38: × | L38: 立即 | M38: ·你触碰一个生命值为0的活体生物，使该生物的伤势立刻稳定下来。该法术对不死生物和构装生物无效。 | N38: 维生术 | O38: Spare the Dying | Q38: √ | X38: √ | AA38: 玩家手册
A39: =施法!J41 -> 0 | B39: 剑刃爆发 | C39: 0 | D39: 咒法 | E39: x | F39: 1动作 | G39: 自身(5尺半径) | H39: V | I39: × | J39: × | K39: × | L39: 立即 | M39: ·你在瞬间制造出一圈半透明的利刃清扫你的周围。法术范围内除你以外的每一个生物都必须成功通过一次敏捷豁免，否则将受到1d6点力场伤害。 ·你到达5级时，该法术的伤害增加1d6（变为2d6）。11级时再加1d6（变为3d6），17级时再加1d6（变为4d6）。 | N39: 剑刃爆发 | O39: Sword Burst | U39: √ | V39: √ | W39: √ | X39: √ | AA39: 剑湾冒险者指南
A40: =施法!J42 -> 0 | B40: 奇术 | C40: 0 | D40: 变化 | E40: x | F40: 1动作 | G40: 30尺 | H40: V | I40: × | J40: × | K40: × | L40: 至多1分钟 | M40: ·你在施法距离内展示出一个低级奇观，以表现你的超自然力。你在施法距离内创造出下列魔法效应之一： →你的声音在1分钟内变得比常人响两倍。 →你在1分钟内使一团火焰闪烁，变亮，变暗或变色。 →你使地面震动1分钟（完全无害）。 →你使某种声音自施法距离内一点瞬间发出，例如雷鸣声，鸦叫声或不祥的低语声。 →你使一扇没有锁上的门或窗瞬间打开或关上。 →你在1分钟内改变自己眼睛的颜色。 ·多次施展该法术时，你可以同时维持最多三个持续1分钟的效应。你也可以用一个动作驱散其中一种效应。 | N40: 奇术 | O40: Thaumaturgy | Q40: √ | AA40: 玩家手册
...

Sheet 图表
A1: 人类 | B1: =主要情况!S3 -> 邪术师 | C1: 法师 | D1: 1d6 | E1: =D14 -> 1d8 | F1: 1d6 | G1: 4 | H1: =D14 -> 1d8 | I1: 1d6 | J1: 2 | K1: =主要情况!W3 -> 5 | L1: 0 | M1: 0 | N1: =主要情况!S3 -> 邪术师 | O1: 法师 | P1: 法术值 | Q1: =主要情况!V11 -> 已知祈唤 | R1: 法术值 | S1: =P35 -> 27 | T1: =主要情况!O25 -> 扇子 | U1: 短棒 | V1: 1d4 | W1: 钝击 | X1: 1 sp | Y1: 轻型 | Z1: 2 | AA1: =背包!B5 -> 0 | AB1: 算盘 | AC1: - | AD1: 2gp | AE1: 2 | AF1: =角色!E10 -> 智者 | AG1: 侍僧Acolyte | AH1: 信仰庇护ShelteroftheFaithful。作为一名侍僧，你与同一信仰的同志互相尊重，并且可以随时主持相应神祇的神圣仪式。当你与冒险同伴遇到你所信仰神祇的神庙，圣坛或其他机构时，你们可能会得到免费的治疗和照料，但你必须为法术提供必须的材料成分。那些与同一信仰的同志会支持你（但仅限你）最基本的生活需求。 | AI1: 侍僧理想 | AJ1: 侍僧牵绊 | AK1: 侍僧缺点 | AL1: 侍僧特点 | AM1: 侍僧技能熟练项 | AN1: 侍僧工具熟练项 | AO1: 侍僧额外语言 | AP1: 侍僧背景装备 | AQ1: 侍僧特殊选项 | BX1: 圣武士 | BZ1: 法师 | CB1: 术士 | CD1: 吟游诗人 | CF1: 牧师 | CH1: 武僧 | CJ1: 游荡者 | CL1: 邪术师 | CN1: 奇械师 | CP1: 战士 | CR1: 游侠 | CT1: 野蛮人 | CV1: 德鲁伊 | CX1: 属性值提升 | CY1: 你可以选择一项属性值提升2点，或是选择两项属性各提升1点。不过你不能通过此特性让属性值超过20。 | CZ1: 0
A2: 半身人 | C2: 术士 | D2: 1d6 | F2: 1d8 | G2: 5 | I2: 1d8 | J2: 3 | L2: 1 | M2: 4 | O2: 术士 | P2: 术法点 | R2: 术法点 | S2: =P56 -> 5 | T2: =主要情况!O26 -> 铁链 | U2: 匕首 | V2: 1d4 | W2: 穿刺 | X2: 2gp | Y2: 灵巧 轻型 投掷(射程20/60) | Z2: 1 | AA2: =背包!B6 -> 0 | AB2: 强酸_小瓶 | AC2: 你可以用一个动作将这小瓶液体泼溅到你身边 5尺内的一个生物身上，或是将小瓶投到至多 20 尺远的地方，并利用冲击打破它。两种情况都可以视为对一个生物或物件发动一次远程攻击，并将强酸视为一件临时武器。命中时，目标受到 2d6点强酸伤害。 | AD2: 25gp | AE2: 1 | AG2: 骗子Charlatan | AH2: 假身份FalseIdentity。你可以伪装成另一个身份，还附带关于该身份的相关的人证物证，并且必须先乔装打扮来让你进入角色。此外，你还可以伪造含有官方格式和私人笔迹的文书，前提是你必须曾见过此类文件以及目标的笔迹以作范本。 | AI2: 骗子理想 | AJ2: 骗子牵绊 | AK2: 骗子缺点 | AL2: 骗子特点 | AM2: 骗子技能熟练项 | AN2: 骗子工具熟练项 | AO2: 骗子额外语言 | AP2: 骗子背景装备 | AQ2: 骗子特殊选项 | BX2: 神圣感知 | BY2: 强大的邪恶存在于你有如带毒的香气，而强大的善良光环于你则如仙乐般悠扬。 你可以使用一个动作扩展你的意识，以侦测此类势力。直到你下回合结束前，你可以对身边60尺范围内进行感测，任何未对你处在全身掩护状态的天界生物、邪魔或不死生物都将被你定位。你感应到范围内生物的种类（天界生物、邪魔、不死生物），不过并不能精确指明（比如“吸血鬼伯爵施特拉德･冯･扎洛维奇 Vampire Count Strahd von Zarovich”）。 在同样的范围内，你也可以侦测任何受到圣居hallow 一类的法术祝福或亵渎的地点或物件。 该特性的可用次数等于1＋你的魅力调整值。而已消耗的特性使用次数，则可以通过完成一次长休进行恢复。 | BZ2: 法师施法 | CA2: 作为一名奥术魔法的研习者，你拥有一本自己的法术书。书中所包含的法术隐约透露着你真正的力量。参考第10章的施法规则，以及第11章的法师法术列表。 戏法 Cantrips 第1级时，你从法师法术列表中选择三个戏法作为已知法术。在获得更高的法师等级后你还可以习得其它的戏法，具体数量参见“法师职业表”中“已知戏法”一栏。 法术书 Spellbook 第1级时，你让一本法术书纪录上六个你自选的1环法师法术。你的法术书储存着你除戏法外的所有已知法术，而你的戏法则直接铭记在你脑海中。 法术的准备和施展 Preparing and Casting Spells “法师职业表”里记录了你用以施展你法师法术的1环及更高环阶法术位数量。施展一个法师法术时，你必须同时消耗其对应环阶的法术位。已消耗的法术位可在完成长休后恢复。 你可以准备一系列符合当前施法条件的法师法术。准备法术时，你从法术书中选择的准备法术总数等于你的智力调整值＋你的法师职业等级（最少为1）。另外，你只能准备已经获得相应环阶法术位的法术。已施展的法术并不会从你的准备列表中移除。 你可以在完成长休后改变你的准备法术列表。准备新的法师法术列表时，你要再花时间研读你的法术书，并重新记忆所准备法术的咒语和施展动作。准备时，你要为你列表上每个法术的每个环阶都花费至少1分钟时间。 施法关键属性 Spellcasting Ability 你的法术来自你专注的研习和记忆，因此智力是你施展法师法术的关键属性。每当你的法术需要施法关键属性时均指向你的智力值。而你法师法术的豁免DC和攻击检定，则使用你的智力调整值。 法术豁免 DC＝8＋你的熟练加值＋你的智力调整值 法术攻击调整值＝你的熟练加值＋你的智力调整值 仪式施法 Ritual Casting 如果你法术书记录了带有仪式标签的法术，则你可以用这些法术进行仪式施法。进行仪式施法时，你不需要准备相应的法术。 法器 Spellcasting Focus 你可以使用奥术法器（详见第5章）来作为施展法师法术的法器。 学习法术 Learning Spells of 1st Level and Higher 你每提升一个法师等级，可以将两项自选的法师法术加入你的法术书中。但是，你只能加入已经获得相应环阶法术位的法术。你在冒险过程中所发现的法术也可以加入到法术书中（详见“你的法术书”边栏）。 | CB2: 术士施法 | CC2: 过去的一个事件激发了你体内先辈的血脉，为你烙上了奥法力量的坚固印记。这股起源于某种存在的魔力驱动着你的法术能力。详见第10章的施法规则及第11章的术士法术列表。 戏法 Cantrips 第1级时，你从术士法术列表里选择四个戏法作为已知法术。在获得更高的术士等级后你还可以习得其它的戏法，具体数量见“术士职业表”中“已知戏法”一栏。 法术位 Spell Slots “术士职业表”中记录了你用以施展你术士法术的1环及更高环阶法术位数量。施展一个术士法术时，你必须同时消耗其对应环阶的法术位。已消耗的法术位可在完成长休后恢复。 已知法术 Spells Known of 1st Level and Higher 第1级时，你从术士法术列表里选择两个1环法术作为已知法术。 “术士职业表”中“已知法术”一栏记录了你获得更多已知法术时的相应等级。但是你只能获取已有相应环阶法术位的法术。 另外，你每提升一个术士等级，都可以从术士法术列表里选择一个新法术来代替一个已知法术列表中的旧法术。但是，你必须拥有新法术的相应环阶法术位。 施法关键属性 Spellcasting Ability 你的魔力来源于你意志的现实投影，因此魅力是你施展术士法术的关键属性。每当你的法术需要施法关键属性时均指向你的魅力值。而你术士法术的豁免DC和攻击检定，则使用你 的魅力调整值。 法术豁免 DC＝8＋你的熟练加值＋你的魅力调整值 法术攻击调整值＝你的熟练加值＋你的魅力调整值 法器 Spellcasting Focus 你可以使用奥术法器（详见第5章），作为你施展术士法术时的法器。 | CD2: 吟游诗人施法 | CE2: 你习得以音乐为媒介随意解构、分解，再重新构造现实的方法。你的法术是融入你纷繁奏乐中的音符，也是你以各种形式谱奏的魔法乐章。 参考第10章的施法规则，以及第11章的吟游诗人法术列表。 戏法 Cantrips 第1级时，你从诗人法术列表中选择两个戏法作为已知法术。在获得更高诗人等级后你还可以习得其它的戏法，具体数 量见“吟游诗人职业表”中“已知戏法”一栏。 法术位 Spell Slots “吟游诗人职业表”中记录了你可用以施展诗人法术的1环及更高环阶法术位数量。施展诗人法术时，你必须同时消耗其对应环阶的法术位。已消耗的法术位可在完成长休后恢复。 已知法术 Spell Known of 1st Level and Higher 第1级时，你从诗人法术列表中选择四个1环法术作为已知法术。 “吟游诗人职业表”中“已知法术”一栏记录了你获得更多已知法术时的相应等级。但是，你只能获取已有相应环阶法术位的法术。 另外，你每提升一个诗人等级，可以从诗人法术列表中选 择一个新法术来代替一个已知法术列表中的旧法术，不过你必须已有新法术的相应环阶法术位。 施法关键属性 Spellcasting Ability 你的魔力源于你注入音乐或演说中的心灵力量，因此魅力是你施展吟游诗人法术的关键属性。每当你的诗人法术需要施法关键属性时均指向你的魅力值。而你诗人法术的豁免DC和攻击检定，则使用你的魅力调整值。 法术豁免 DC＝8＋你的熟练加值＋你的魅力调整值 法术攻击调整值＝你的熟练加值＋你的魅力调整值 仪式施法 Ritual Casting 如果你已知法术列表中的一个法术带有仪式标签，则你可以用这些法术进行仪式施法。 法器 Spellcasting Focus 你可以使用乐器（见第5章）作为施展诗人法术的法器。 | CF2: 牧师施法 | CG2: 你作为神圣力量的导体得以施展牧师法术。参考第10章的施法规则，以及第11章的牧师法术列表。 戏法 Cantrips 第1级时，你选择三个牧师法术列表中的戏法作为已知法术。在获得更高的牧师等级后你还可以习得其它的戏法，具体数据参见“牧师职业表”中“已知戏法”一栏。 法术的准备与施展 Preparing and Casting Spells “牧师职业表”里记录了你用以施展牧师法术的1环及更高环阶法术位数量。施展一个牧师法术时，你必须同时消耗其对应环阶的法术位。已消耗的法术位可在完成长休后恢复。 你可以准备牧师法术列表中所有符合当前施展条件的法术。准备法术时，你所准备法术的总数等于你的感知调整值＋你的牧师职业等级（最少可以准备一个）。另外，你只能准备已经获得相应环阶法术位的法术。另外，已施展的法术并不会从你的准备列表中移除。 你可以在完成长休后改变你的准备法术列表。准备新的牧 师法术列表时，你要再花时间进行祈祷和冥想。准备时，你要为你列表上每个法术的每个环阶都花费至少1分钟时间。 施法关键属性 Spellcasting Ability 你的法术力量来源于你对神祇的信仰，因此感知是你施展牧师法术的关键属性。每当你的牧师法术需要施法关键属性时均指向你的感知值。而你牧师法术的豁免DC和攻击检定，则使用你的感知调整值。 法术豁免 DC＝8＋你的熟练加值＋你的感知调整值 法术攻击调整值＝你的熟练加值＋你的感知调整值 仪式施法 Ritual Casting 如果你所准备牧师法术中的一个法术有带仪式标签，则你可以用这些法术进行仪式施法。 法器 Spellcasting Focus 你可以使用圣徽（见第5章）作为施展牧师法术的法器。 | CH2: 武僧无甲防御 | CI2: 第1级起，未着装任何护甲也没持用盾牌时，你的AC值等于10＋你的敏捷调整值＋你的感知调整值。 | CJ2: 游荡者专精 | CK2: 第1级起，你选择两个已有技能熟练项，或者一个技能熟练项和盗贼工具熟练项。此后你进行该项目的检定时，可以使用双倍的熟练加值。 第6级时，你可以再选择另外两个已有的技能熟练项（或盗贼工具熟练项）从该特性中获益。 | CL2: 异界宗主 | CM2: 第1级时，你就跟某个异界的存在订下契约。你可以从至高妖精Archfey、邪 Fiend、旧日支配者Great Old One等选项中选择其一。 随后你将在第 1、第 6、第 10、第14级获得相应的职业特性。 你可以在拓展之中找到更多的邪术师异界宗主。 | CN2: 魔法工艺 | CO2: 在第1级，你将学习如何在平凡的物品中注入魔法的火花。要使用这个能力，你必须手持修补工具，或其他工匠工具。然后花费一个动作触摸一个微小的非魔法物体，从以下魔法属性中选择一个赋予它： ·该物体提供5尺半径的明亮照明，以及该范围外5尺范围的微光照明。 ·无论何时，只要该物品被生物触碰，就会发出可在10英尺外听到的录音信息。录入的信息在你将此属性赋予对象时决定，且时长不可超过6秒。 ·物品不断地发出一种气味或一种非语言的声音（风声、浪声、鸟叫或类似的声音）。这一现象最多能传播10英尺远。 ·一个静态的视觉效果出现在物体的表面上。这个效果可以是一幅图片，最多25个单词的文本，线条和形状，或者这些元素的混合，如你所愿。 所选的魔法属性持续时间无限。你能够以一个动作触摸对象来消除这一魔法属性。 你能够通过此特性将魔力赋予多个物品，每次使用该特性时都需要触摸一个物品，并且单个物品一次只能承载一种魔法属性。你能够使用该特性影响的物品的最大数量等于你的智力调整值（最少一个物品）。如果你试图超过最大值，最老的魔法属性将立即结束，然后新的魔法属性生效。 | CP2: 战士战斗风格 | CQ2: 你专精于一种战斗风格，并从下列选项中选择。另外，即使你有多次选择战斗风格的机会，也不能多次选择同一个战斗风格。[注意：不要在这里选好下拉之后就不管它了，请务必清晰记录你究竟选择了什么战斗风格] 箭术Archery 你使用远程武器进行攻击检定时具有+2加值。 防御Defense 着装护甲时，你的AC获得+1加值。 对决Dueling 单手持用一把近战武器，且并未同时持用其他武器时，你用该武器攻击的伤害掷骰获得+2加值。 巨武器战斗Great Weapon Fighting 双手持用一把近战武器发动攻击时，如果你的伤害掷骰掷出1或2，则可以选择重掷。不过哪怕其仍是1或2，你都必须接受重掷的数值。此外，该武器必须具有双手或两用属性。 守护Protection 当一个你能看见的生物攻击你身边5尺内除你之外的目标时，你可以用反应迫使该攻击的攻击检定具有劣势。此时你必须持用盾牌。 双武器战斗Two-Weapon Fighting 使用两把武器战斗时，你可以将相应属性调整值加到第二次攻击的伤害上。 | CR2: 宿敌 | CS2: 第1级起，你针对一种特定类型敌人的研究令你有着充足的经验用以追踪、狩猎乃至与之交流。 从下列种类中选择其一作为宿敌：异怪、野兽、天界生物、构装生物、龙、元素生物、精类生物、邪魔、巨人、怪兽、泥怪、植物、不死生物。或者作为另一种方案，你也可以选择两个类人生物种族（例如豺狼人gnolls 和兽人orcs）作为宿敌。 追踪宿敌时，你的感知（求生）检定，以及回想关于宿敌信息时进行的智力检定具有优势。 获得该特性时，如果你选择的宿敌具有语言能力，则你还可以学会宿敌所知晓的一门语言。 第6和第14级时，你将分别获得一个额外的宿敌以及相关语言。另外，随着等级的提升，你所选择的宿敌应该与你在冒险中所遭遇怪物的种类层次相符。 | CT2: 狂暴 | CU2: 你带着原初的狂怒作战。你可以在自己回合内以一个附赠动作进入狂暴。 狂暴持续期间，只要你未着装重甲就获得以下增益： • 你进行力量检定和力量豁免时具有优势。 • 你用力量值发动近战武器攻击时的伤害掷骰获得加值。此加值随你的野蛮人等级提升而增加，具体见“野蛮人职业表” 中“狂暴伤害”一栏。 • 你拥有钝击，穿刺和挥砍伤害的抗性。 拥有施法能力的角色无法在狂暴持续期间施展法术或进行法术专注。 你的狂暴状态维持1分钟。如果你在狂暴其间陷入昏迷，或者，如果你从自己上回合结束开始到本回合结束时都未攻击任何敌对生物也未受到伤害，则狂暴提前结束。你也可以在自己回合里以一个附赠动作主动结束狂暴状态。 “野蛮人职业表”中根据你的野蛮人等级给出了相应的狂暴次数。如果你用光了这些次数，则必须完成一次长休才能再次使用狂暴。 | CV2: 德鲁伊语 | CW2: 你习得德鲁伊语——即一种德鲁伊间的秘密语言。你可以说这门语言并用它留下隐藏的信息。 懂得这门语言的人（包括你自己）会自动注意到此信息，而不懂此语言的人通过一次DC15的感知（察觉）检定后可以注意到其存在，不过不能用非魔法手段读懂。 | CX2: 警觉 | CY2: 经常对危机保持警惕，让你获得下列增益： • 你的先攻获得+5加值。 • 你在意识清醒时无法被突袭。 • 你看不到的生物对你发动攻击检定时，无法因此获得优势。 | CZ2: 1
A3: 精灵 | C3: 吟游诗人 | D3: 1d8 | F3: 1d10 | G3: 6 | I3: 1d10 | J3: 4 | L3: 2 | M3: 6 | O3: 吟游诗人 | P3: 激励骰 | R3: 激励骰 | S3: =P77 -> 1d8 | T3: =主要情况!O27 -> 0 | U3: 巨棒 | V3: 1d8 | W3: 钝击 | X3: 2 sp | Y3: 双手 | Z3: 10 | AA3: =背包!B7 -> 0 | AB3: 炽火胶_扁瓶 | AC3: 一种粘稠的流体，其一旦接触空气就会引起自燃。你可以用一个动作将这小瓶液体投到至多20尺远的地方，并利用冲击打破它。这个动作视为对一个生物或物件发动一次远程攻击，并将炽火胶视为一件临时武器。命中时，目标在它每回合开始时受到1d4点火焰伤害。被命中生物可以使用动作进行一次DC10的敏捷检定，以扑灭火焰来结束该伤害效应。 | AD3: 50gp | AE3: 1 | AG3: 罪犯Criminal | AH3: 罪犯联络员CriminalContact。你有一个可靠可信的联络员，来帮你组织进罪犯们组成的联系网中。即使遥隔千里你也知道如何从联络人处收发信息。此外，你还知道哪些人能为你捎信，他们可能是本地的信使，可贿赂的商队主管，或是衣衫褴褛的水手。 | AI3: 罪犯理想 | AJ3: 罪犯牵绊 | AK3: 罪犯缺点 | AL3: 罪犯特点 | AM3: 罪犯技能熟练项 | AN3: 罪犯工具熟练项 | AO3: 罪犯额外语言 | AP3: 罪犯背景装备 | AQ3: 罪犯特殊选项 | BX3: 圣疗 | BY3: 你的触碰溢满祝福，可以医治伤口。你获得一个治疗能量池，其内的治疗能量在每次完成长休后自动补满。治疗能量池储备的可恢复生命值总值等于你的圣武士职业等级×5。 你可以用一个动作触碰一个生物，并抽取治疗能量池中的能量恢复该生物的生命值，其恢复量最多等于你治疗能量池中剩余的治疗量。 此外，你也可以使用 5 点治疗量治愈目标生物身上的一种疾病，或者祛除一种中毒效应。你可以在一次圣疗中治愈复数的疾病并祛除复数的毒素，但你需要为每一种疾病和毒素分别支付治疗量。 该职业特性对不死生物和构装生物无效。 | BZ3: 奥术回想 | CA3: 你学会了通过研读法术书来恢复魔法能量的办法。 你可以每日使用一次奥术回想，以在你完成一次短休后恢复若干已消耗的法术位。 所恢复的法术位环阶总和不得大于你法师等级的一半（向上取整），且任何一枚法术位的环阶都必须小于6环。 例如，作为一名4级法师时，你可恢复环阶总数最多为2的法术位。你可以选择恢复一枚2环法术位或两枚1环法术位。 | CB3: 术法起源 | CC3: 选择一个术法起源作为你天赋魔力的源泉。你可在龙族血脉Draconic Bloodline 或狂野魔法Wild Magic 中选择其一。 随后，你将在第1、第6、第14、第18级获得相应起源的职业特性。 你可以在拓展中找到更多的术法起源。 | CD3: 诗人激励 | CE3: 从第1级起，你可以用热血的话语和音乐激励他人。此时， 你可以在自己回合内用一个附赠动作指定身边60尺内一个能听到你声音的生物（不能指定你自身），并使该生物获得一个诗人激励，即一个d6的激励骰。 在接下来的10分钟内，该生物在进行单次属性检定、攻击检定、豁免检定时可以使用该激励骰，以将其结果加到掷骰结果中。该生物可以在d20结果掷出后，DM宣布结果前决定是否使用诗人激励。 而诗人激励一旦使用即被消耗掉。一个生物同一时间里只能保有一个诗人激励。 你能够使用该特性的次数等于你的魅力调整值（最低一次）。完成一次长休后，你将重获所有消耗掉的诗人激励次数。 你产生的激励骰大小可以在达到本职业的特定等级时增大。第5级时为d8，第10级时为d10，而第15级时为d12。 | CF3: 神圣领域 | CG3: 你将选择一个与你所信仰神祇的神职相关的神圣领域。你可以从知识 Knowledge、生命 Life、光明 Light、自然 Nature、 风暴 Tempest、诡术 Trickery 或者战争 War 中选择其一。 一些领域其领域法术可能并不在牧师法术列表中，此时如果你选择了该领域，则你视该领域的领域法术为你的牧师法术。 领域法术 Domain Spells 每个领域都有其相应的领域法术列表。当你获得表中所对应的牧师等级时，你将同时习得这些法术。领域法术一旦习得，将会一直在你的准备法术列表中，且不计入你的每日准备法术上限。 任何领域法术对你而言都是牧师法术，而不论其是否在牧师法术列表之上。 拓展中存在更多牧师神圣领域。 | CH3: 武艺 | CI3: 第1级时，你修行的武艺让你使用徒手打击和武僧武器时得心应手。武僧武器包括短剑和所有不含双手与重型属性的简易近战武器。 未着装任何护甲也没持用盾牌时，如果你徒手或只持用武僧武器，则你发动的攻击拥有下列增益： • 你使用徒手打击或武僧武器进行攻击时，可以用敏捷值代替力量值进行攻击检定和伤害掷骰。 • 你使用徒手打击或武僧武器进行攻击时，可以选择用d4骰代替原本的伤害掷骰。该骰子将随武僧职业等级的提升而增大，具体数据见“武僧职业表”中“武艺”一栏。 • 你使用徒手打击或武僧武器执行攻击动作时，可以在自己回合内以附赠动作发动一次徒手打击。例如，你执行攻击动作并使用长棍发动攻击时，若你本轮没有执行任何附赠动作，则可以用附赠动作来发动一次徒手打击。 一些宗派的武僧会使用一些奇异的武僧武器，比如铁链连接的两根短棒（双截棍 nunchaku），或者带直刃的镰刀（单镰kama）。无论你使用什么武器，其属性数据都参考与其相似的常规武器属性数据。具体的武器数据见第5章。 | CJ3: 偷袭 | CK3: 第1级起，你就知道如何精确地攻击分心的敌人。每当你的攻击命中一个生物时，如果该攻击的攻击检定带有优势，则可以造成额外1d6的伤害。 该伤害每回合可以产生一次，且造成伤害的攻击必须使用带灵巧属性的武器或远程武器。 如果目标生物身边5尺内还有其他与之对敌者，且该对敌者并未处于失能状态，则只要你的攻击检定没有劣势，就可以发动偷袭。 你的偷袭伤害也将会随游荡者职业等级的提升而提高，其具体数值见“游荡者职业表”。 | CL3: 契约魔法 | CM3: 你的法术力量源于你的奥秘研究和宗主的魔法馈赠。参考第10章的施法规则，以及第11章的邪术师法术列表。 戏法 Cantrips 你从邪术师法术列表中选择两个戏法作为已知法术。在获得更高的邪术师等级后你还可以习得其它的戏法，具体数据见“邪术师职业表”中“已知戏法”一栏。 法术位 Spell Slots “邪术师职业表”里记录了你可用以施展邪术师法术的1环至5环法术位数量。表格中还记录了法术位对应的法术环阶，且你所有的法术位都属于同一环阶。施展1环或更高环阶的邪术师法术时，都需要消耗一枚法术位。已消耗的法术位可在完 成长休或短休后恢复。 例如，达到第5级时，你总共具有两枚3环法术位。你施展1环法术巫术箭witch bolt 时，必须消耗消耗这些法术位其中之一，并把它作为一个3环法术施放。 已知法术 Spell Known of 1st Level and Higher 第1级时，你从邪术师法术列表里选择两个1环法术作为已知法术。 “邪术师职业表”中“已知法术”一栏记录了你获得更多法术时的相应等级。每个被选的法术都必须在当前等级拥有可用以施展该法术的法术位，具体见表。比如，当你达到第6级时，你将获得一个1环、2环或3环的新邪术师法术。 另外，当你提升本职的职业等级时，你可以从邪术师法术列表里选择一个新法术来代替一个旧的邪术师已知法术，但是你的角色必须拥有用以施展新选法术的可用法术位。 施法关键属性 Spellcasting Ability 魅力是你施展邪术师法术的关键属性。每当你的法术需要施法关键属性时均指向你的魅力值。而你邪术师法术的豁免DC和攻击检定，则使用你的魅力调整值。 法术豁免 DC＝8＋你的熟练加值＋你的魅力调整值 法术攻击调整值＝你的熟练加值＋你的魅力调整值 法器 Spellcasting Focus 你可以使用奥术法器（详见第5章）作为你施展邪术师法术的法器。 | CN3: 奇械师施法 | CO3: 你已经学习了魔法的工作原理，知道如何引导魔法进入物体，以及如何唤醒魔法。因此，你获得了有限的施法能力。在旁观者看来，你不会用传统的方式施法——你看起来好像在通过各种物品创造奇迹。 必备工具 你通过你的工具产生你的奇械师法术效果。当你使用施法特性来施展法术时，必须手持一个法器——通常是盗贼工具或工匠工具。你必须熟练这一工具才能将它作为法器使用。这些工具的描述请参见《玩家手册》第五章“装备”。 当你在第二级获得物品注法特性后，你也能使用任何你注入魔法的物品来作为法器使用。 戏法 在第1级，你从奇械师法术列表中习得两个戏法。在更高的等级，你能够根据“奇械师职业表”习得更多戏法。 当你提升一个奇械师等级时，你能够从奇械师法术列表中习得一个新的戏法来替换一个原有的已知戏法。 法术的准备和施展 “奇械师职业表”显示出你有多少能用于施法的法术位。施展某个奇械师法术时，你必须同时消耗其对应环阶的法术位。而已消耗的法术位则可以通过完成一次长休进行恢复。 你需要从奇械师法术列表中选择想要准备的法术，你能选择的准备法术总数等于你的智力调整值＋你奇械师职业等级的一半（向下取整）（最少为1）。你只能准备已经获得相应环阶法术位的法术。另外，已施展的法术并不会从你的准备列表中移除。 你可以在完成长休后改变你的准备法术列表。如需准备新的奇械师法术，你需要花时间来调整你的法器：每个法术要花费至少1分钟的时间。 施法关键属性 你对魔法理论的理解使你能够以更高超的技法来使用这些法术，因此智力是你的施法关键属性。每当你的法术需要施法关键属性时均指向你的智力值。而你奇械师法术的豁免DC和攻击检定，也使用你的智力调整值。 法术豁免DC＝8＋你的熟练加值＋你的智力调整值 法术攻击调整值＝你的熟练加值＋你的智力调整值 仪式施法 如果你准备了带有仪式标签的法术，则你可以用这些法术进行仪式施法。 | CP3: 回气 | CQ3: 你拥有少量精力储备可用来保护自己免受伤害。你可以在自己回合内用一个附赠动作恢复生命值，其总值为1d10＋你的战士职业等级。 你必须完成一次短休或长休才能再次使用该特性。 | CR3: 自然探索者 | CS3: 你对某种自然环境特别熟悉，并适应了在其中行走及生存。 从下列类别中选择一种偏爱地形：极地 arctic、海岸 coast、荒漠 desert、丛林 forest、草原 grassland、山地 mountain、沼泽swamp 或幽暗地域 Underdark。当你进行与偏好地形相关的智力或感知检定时，如果你拥有该技能的熟练项，则在检定时加入双倍熟练加值。 当你在偏好地形上移动一小时或更长时间时，你获得以下增益： • 你的队伍旅行时不会因困难地形而变慢 • 除非受魔法效应影响，否则你的队伍不会迷路 • 旅行时，即使你进行另一项活动（如觅食、导航或追踪），仍能对危险保持警觉 • 独自旅行时，你能够保持隐匿状态以正常步调移动 • 觅食时，你会发现两倍的食物 • 追踪其他生物时，你还能了解他们的确切数量、体型以及离开踪迹的时间 你在第6级和第10级时将分别获得一个额外的偏好地形。 | CT3: 野蛮人无甲防御 | CU3: 未着装任何护甲时，你的AC等于 10＋你的敏捷调整值＋你的体质调整值。使用盾牌不会影响你从此特性获益。 | CV3: 德鲁伊施法 | CW3: 你掌握自然世界的神圣本质，并依你的意志施展法术对其进行重塑。参考第10章的施法规则及第11章的德鲁伊法术列表。 戏法 Cantrips 第1级时，你选择两项德鲁伊法术列表中的戏法作为已知法术。在获得更高的德鲁伊等级后你还可以习得其它的戏法，具体数据参见“德鲁伊职业表”中“已知戏法”一栏。 法术的准备和施展 Preparing and Casting Spells “德鲁伊职业表”里记录了你用以施展德鲁伊法术的1环及更高环阶法术位数量。施展一个德鲁伊法术时，你必须同时消耗其对应环阶法术位。已消耗的法术位可在完成长休后恢复。 你可以准备德鲁伊法术列表中所有符合当前施展条件的法术。准备法术时，你所准备法术的总数等于你的感知调整值＋你的德鲁伊职业等级（最少可以准备一个）。另外，你只能准备已经获得相应环阶法术位的法术。另外，已施展的法术并不会从你的准备列表中移除。 你可以在完成长休后改变你的准备法术列表。准备新的德鲁伊法术列表时，你要再花时间进行祈祷和冥想。准备时，你要为你列表上每个法术的每个环阶都花费至少1分钟时间。 施法关键属性 Spellcasting Ability 你的法术力量源于你对自然的信仰与同调，因此感知是你施展德鲁伊法术的关键属性。每当你的德鲁伊法术需要施法关键属性时均指向你的感知值。而你德鲁伊法术的豁免DC和攻击检定，则使用你的感知调整值。 法术豁免 DC＝8＋你的熟练加值＋你的感知调整值 法术攻击调整值＝你的熟练加值＋你的感知调整值 仪式施法 Ritual Casting 如果你所准备德鲁伊法术中的一个法术有带仪式标签，则你可以用这些法术进行仪式施法。 法器 Spellcasting Focus 你可以用德鲁伊法器（详见第5章）作为你施展德鲁伊法术的法器。 | CX3: 运动员 | CY3: 你接受的全面肉体锻炼使你获得下列增益： • 你的力量或敏捷增加1，上限为20。 • 你陷入倒地状态时，起立所需要花费的移动力为5尺 • 攀爬无需额外消耗移动力 • 你在进行助跑调高或跳远时只需要移动5尺，而不是10尺。 | CZ3: 2
A4: 半精灵 | C4: 牧师 | D4: 1d8 | F4: 1d12 | G4: 7 | I4: 1d12 | J4: 5 | L4: 3 | M4: 14 | O4: 牧师 | P4: 引导神力 | R4: 引导神力 | S4: =P119 -> 1 | U4: 手斧 | V4: 1d6 | W4: 挥砍 | X4: 5gp | Y4: 轻型 投掷(射程20/60) | Z4: 2 | AA4: =背包!B8 -> 0 | AB4: 箭(20) | AC4: - | AD4: 1gp | AE4: 1 | AG4: 密探Spy | AH4: 罪犯联络员CriminalContact。你有一个可靠可信的联络员，来帮你组织进罪犯们组成的联系网中。即使遥隔千里你也知道如何从联络人处收发信息。此外，你还知道哪些人能为你捎信，他们可能是本地的信使，可贿赂的商队主管，或是衣衫褴褛的水手。 | AI4: 密探理想 | AJ4: 密探牵绊 | AK4: 密探缺点 | AL4: 密探特点 | AM4: 密探技能熟练项 | AN4: 密探工具熟练项 | AO4: 密探额外语言 | AP4: 密探背景装备 | AQ4: 密探特殊选项 | BX4: 圣武士战斗风格 | BY4: 第2级起，你将精进于一种战斗风格，从下列选项中选择其一。另外，即使你有多次选择战斗风格的机会，也不能重复选择同一个战斗风格。[注意：不要在这里选好下拉之后就不管它了，请务必清晰记录你究竟选择了什么战斗风格] 防御Defense 着装护甲时，你的AC获得 +1 加值。 对决Dueling 单手持用一把近战武器，且并未同时持用其他武器时，你使用该武器进行攻击的伤害掷骰获得+2加值。 巨武器战斗Great Weapon Fighting 双手持用一把近战武器发动攻击时，若你的伤害掷骰掷出1或2，则可以选择重掷。不过哪怕其仍是1或2，你都必须接受重掷的数值。此外，该武器必须具有双手或两用属性。 守护Protection 当一个你能看见的生物攻击你身边5尺内除你之外的目标时，你可以用反应迫使该攻击的攻击检定具有劣势。你必须持用盾牌以实现该效果。 | BZ4: 奥术传承 | CA4: 第2级时，你选择一种奥术传承以使你的训练专注于八个学派之一。从防护、咒法、预言、附魔、塑能、幻术、死灵、变化各学派中选择其一。 随后，你将在第2、第6、第10、第14级时获得所选学派相应的特性。拓展中存在更多的学派。 | CB4: 魔力泉涌 | CC4: 第2级时，你解除了体内魔力之源的封印，从中涌现的魔力体现为你的可用术法点。你可以使用术法点创造各种魔法效应。 术法点 Sorcery Points 开始时，你拥有2个术法点。此后你每提升一个术士等级，都会获得更多的术法点，详见“术士职业表”中“术法点”一栏。你的术法点永远不能超过表中所列对应你当前等级的数值。 而已消耗的术法点则可以通过完成一次长休进行恢复。 灵活施法 Flexible Casting 你可以使用术法点来获得额外的法术位，或是消耗法术位来换取额外的术法点。随着术士等级的提升，你还可以学会其他术法点的使用方法。 生成法术位 Creating Spell Slots。你可以在自己回合内以附赠动作将未使用的术法点转换为法术位。表格“生成法术位”中列出了生成各法术位所需的术法点数。另外，你无法生成高于 5 环的法术位。以此方式生成的法术位将在完成一次长休后消散。 生成法术位 Creating Spell Slots 法术位环阶 术法点消耗 1环 2 2 环 3 3 环 5 4 环 6 5 环 7 法术位转换术法 Converting a Spell Slot to Sorcery Points。你可以在自己回合内使用附赠动作将未使用的法术位转化为术法点。你消耗一枚法术位并获得等于该法术位环阶的术法点。 所有你以该特性生成的法术位，在你完成一次长休后也将随之消失。 | CD4: 万事通 | CE4: 第2级起，在你进行属性检定时，如果检定结果不包含你的熟练加值，则你可以将自身熟练加值的一半（向下取整）加入到检定结果中。 | CF4: 引导神力 | CG4: 第2级时，你获得引导神祇所授予神圣能量的能力，所引导的能量将用以实现各种魔法效应。你最初将获得两种效应： 驱散不死生物和另一个与你所选领域相关的效应。随着你在冒险中提升等级，一些领域会赋予更多额外的效应，具体信息可以参考相应领域的描述内容。 引导神力最终产生的效应由你自行选择。引导神力后，你必须完成一次短休或长休才能重新使用该特性。 一些引导神力的效应需要豁免，其豁免DC等于你的牧师法术豁免DC。 第6级起，你可以在两次休息之间使用两次引导神力，第18级后可以使用三次。完成一次短休或长休后，你将重新获得所有消耗掉的引导神力次数。 引导神力：驱散不死生物Channel Divinity: Turn Undead 你以一个动作展示你的圣徽，并说出一段谴责不死生物的祷言。你身边30尺范围内能够看到圣徽或听到你祷言的不死生物必须进行一次感知豁免，豁免失败则受到驱散，其效应持续1分钟或直到其受到任何伤害。 一个被驱散的生物必须花费其回合内的所有速度尽力远离你，而且无法主动靠近你30尺内。被驱散的生物无法使用反应，只能使用既有的疾走Dash动作或从任何妨碍他们移动的效应中挣脱。该生物无路可走时会使用“回避Dodge”动作。 | CH4: 气 | CI4: 第2级起，你掌握一股名为气的神秘能量。此后你将拥有一定数量的气作为储备。而气的储备量由你的武僧等级决定，具体数值见“武僧职业表”中“气”一栏。 你可以消耗气以行使各种特性。一开始你掌握三种特性：疾风连击，坚强防御，飞檐走壁。此后，随着等级的提升你将习得更多的特性。 消耗掉的气必须在你短休或长休时完成至少 30 分钟的冥想，才能重获所有消耗掉的气值。 一些特性需要目标进行豁免检定来抵抗你特性造成的效应。其豁免DC如下： 气豁免 DC＝8＋你的熟练加值＋你的感知调整值 疾风连击 Flurry of Blows 你在自己回合内执行攻击动作后，可立即消耗1点气并以一个附赠动作发动两次徒手打击。 坚强防御 Patient Defense 你在自己回合内，可以消耗1点气，并以一个附赠动作的形式来执行回避 Dodge 动作。 飞檐走壁 Step of the Wind 你在自己回合内，可以消耗1点气，并以一个附赠动作的形式来执行撤离 Disengage 动作或疾走 Dash 动作，同时使你该回合内的跳跃距离翻倍。 | CJ4: 盗贼黑话 | CK4: 作为一名游荡者，你在平时的练习中学会了盗贼间的黑话。盗贼黑话是一门混合了土话、术语和密语的秘密语言，掌握这门语言后，你可以在平时对话中不落痕迹的加入隐藏信息。 而只有另一个懂盗贼黑话的生物才能看懂这些隐藏信息。不过这种交流方式需要花费四倍于直接交流所需要的时间。 另外，你还习得一套用以传达简单短小信息的秘密符文和标识。 它能发布的内容诸如某个地区是否危险，是否受盗贼公会管辖，附近是否有战利品，附近的人是否好主顾或者路上是否有安全的房屋以供庇护。 | CL4: 魔能祈唤 | CM4: 你在神秘学识的研习过程中发掘出魔能祈唤的方式，这些禁忌的知识残章让你获得了持久的魔法能力。 第2级时，你获得两种自选的魔能祈唤（祈唤的具体内容见后文）。在获得更高的邪术师等级后你还可以习得其它的魔能祈唤，具体数据见“邪术师职业表”中“已知祈唤”一栏。 另外，你提升本职的等级时，可以用新的祈唤替换一个已学会的祈唤，但你的角色必须满足学习新祈唤的先决条件。 | CN4: 物品注法 | CO4: 在第2级，你获得为普通物品注入魔法的能力。使用此特性创造的魔法物品是永久性魔法物品的原型。 已知注法 当你获得这个特性时，从职业描述末尾的“奇械师注法”列表中选择选择四个奇械师注法习得。当你提升奇械师等级时，还能够根据“奇械师职业表”习得更多注法。 当你提升一个奇械师等级时，你能够习得一个新的奇械师注法来来替换一个原有的已知注法。 为物品进行注法 每当你完成一个长休后，你可以触摸一个非魔法的物体，使用奇械师注法来把它变成一个魔法物品。注法只能作用于注法描述中写明的指定类型物品。如果该物品需要调谐，你可以在为物品进行注法的那一刻调谐到它，或者你可以放弃调谐，以便其他人能够调谐到该物品。如果你决定以后与这个物品进行调谐，你必须进行通常的调谐程序（参见《地下城主指南》第136页中的“调谐”）。 你的注法持续时间无限，但当你死亡时，注法会在你智力调整值的天数后消失（至少1天）。如果你将某个注法从已知中替换掉，该注法的效果也将消失。 你能在一次长休后为复数物品进行注法；注法物品的最大数量请参见“奇械师职业表”。你必须触摸每一个物体，且一种注法在同一时间内只能存在于一个物品上。如果你试图超过你的最大注法量，则最旧的注法立即结束，然后新的注法适用。 | CP4: 动作如潮 | CQ4: 第2级起，你可以在短时间内突破极限，以使你在自己回合内执行一个额外的动作。 该特性在使用后必须完成一次短休或长休才能再使用。第17级起，你可在休息前使用两次该特性，但每一回合只能使用一次。 | CR4: 游侠战斗风格 | CS4: 第2级起，你将精进于一种战斗风格，从下列选项中选择其一。另外，即使你有多次选择战斗风格的机会，也不能重复选择同一个战斗风格。[注意：不要在这里选好下拉之后就不管它了，请务必清晰记录你究竟选择了什么战斗风格] 箭术Archery 使用远程武器进行攻击检定时具有+2加值。 防御Defense 着装护甲时，你的AC获得+1加值。 对决Dueling 单手持用一把近战武器，且并未同时持用其他武器时，你用该武器攻击的伤害掷骰获得+2加值。 双武器战斗Two-Weapon Fighting 使用两把武器战斗时，你可以将相应属性调整值加到第二次攻击的伤害上。 | CT4: 鲁莽攻击 | CU4: 第2级起，你可以抛弃一切防御的执念进行狂乱的攻击。你在自己回合内发动第一次攻击时，可以选择发动鲁莽攻击。 使用此特性后，你本回合内所有使用力量值发动的近战武器攻击具有优势。 此后，所有对你发动的攻击检定也将具有优势，且该优势持续存在至你的下个回合。 | CV4: 荒野形态 | CW4: 第2级起，你可以用动作以魔力变化为曾见识过的野兽形态。该特性可以使用两次，且在完成一次短休或长休后，你将重新获得所有消耗掉的荒野形态次数。 你的德鲁伊职业等级决定了你可以变化的野兽种类，你可以变化成任意没有飞行或游泳速度且挑战等级为1/4 或更低的野兽形态。 野兽形态 Beast Shapes 等级 最高CR 限制 范例 2nd 1/4 没有飞行或游泳速度 狼 wolf 4th 1/2 没有飞行速度 鳄鱼 crocodile 8th 1 － 巨鹰 giant eagle 你可以在数个小时里保持着野兽形态，其持续时间具体数值等于你的德鲁伊职业等级的一半（向下取整）。你可以在持续时间过后恢复原形，或者你也可以再次使用此特性来维持变形。 另外，你也可以在你的回合内用一个附赠动作来恢复原形。在你陷入昏迷、生命值为0或者死亡的时候，变形将自动解除。 你变形时必须遵从以下规则： • 你的游戏数据替换为新形态的数值，但你仍保持你的阵营、个性，以及智力值、感知值、魅力值。你保留技能与豁免的熟练项，并且获得新形态的技能和豁免熟练项。如果新形态有你已具有的的熟练项且该熟练项的加值高于你的熟练加值，则使用新形态的熟练加值。你不能使用新形态可能拥有的传奇动作或巢穴动作。 • 变形后，你使用新形态的生命值和生命骰。变回原形时，你的生命值恢复变形之前的数值。而任何让你的生命值降至0的伤害，都可以使你变回原形并承受该伤害的溢出伤害量。 例如，你在动物形态下受到了10点伤害而你只剩1点生命值，则你变回原形并受到9点伤害。只要超过的伤害没有将你原形的生命值降至0，你就不会因此陷入昏迷。 • 你不能施法，并且任何说话或者需要用手的动作，在你处于野兽形态时都将受到限制。变形不会打断你正在专注的法术，也不会妨碍你执行作为已施展法术（例如召雷术call lightning）一部分的一些动作。 • 你保持从职业、种族或其它来源特性的收益，并且可以在新形态身体能力允许下使用这些特性。不过，你无法使用任何原有的特殊感官（例如黑暗视觉），除非你的新形态也具有这种感官。 • 变形时，你可以选择将你的装备丢在所处空间，或者将其融入新形态，又或者直接着装在身上。新形态直接着装的装备可以如常起作用，但DM有权基于新形态的体型和身姿作出判断，并最终决定新形态使用该装备是否合理。装备不会改变大小来适应新形态，新形态无法着装一些装备时，该装备会掉落你所处空间或融入新形态中。融入新形态的装备失去其效应，且在你变回原形时才能恢复。 | CX4: 演员 | CY4: 精通于模仿和演戏，让你获得下列增益： • 你的魅力增加1，上限为20。 • 当你试图将自己扮演成另一个人时，你进行魅力（欺瞒）和魅力（表演）检定时具有优势。 • 你可以模仿另一个生物的说话口吻和声音。前提是你必须听过被模仿者至少1分钟的说话或发声。 对方聆听你的模仿时可以进行一次感知（洞悉）检定，并与你的魅力（欺瞒）检定进行对抗，若对方胜出便会意识到声音是模仿出来的。 | CZ4: 3
